Workbook

Sheet Nasil_Kullanilir
A1: Bölge KPI Kontrol Platformu
A2: Tüm mağaza ve rakamlar SAHTEDİR. Orijinal dosyanın yapısı (kaynak sayfalar, genel tablo, hedefler, performans puanı) sahte veriyle yeniden kurulmuştur.
A4: Her ay
A5: 1. Sistem raporları ilgili kaynak sayfalara yapıştırılır: Satis, PnL, CRM, Paket_Servis, Urun_Karmasi, Fire_Envanter, Egitim, Personel, Kahve_Sohbeti, Sikayet, Denetim.
A6: Her kaynak sayfada A sütunu anahtar formülüdür (Dönem|Mağaza); veri B sütunundan başlar.
A7: 2. Genel_Tablo sayfasında dönem seçilir. Her mağaza tek satırda, tüm göstergeler hedefe göre yeşil/kırmızı görünür.
A8: 3. Performans_Puani: her gösterge hedefi tuttuysa katsayısı kadar puan verir; toplam 100 üzerindendir ve mağazalar sıralanır.
A9: 4. Aylık toplantıda Genel_Tablo üzerinden sapmalar konuşulur; P&L sapma açıklamaları PnL sayfasındaki Açıklama sütunundan gelir.
A11: Hedefler ve katsayılar Hedefler sayfasından değiştirilir. Yön: '≥' büyük olması iyi, '≤' küçük olması iyi.
A13: Kısaltmalar
A14: ADT: günlük ortalama işlem (adisyon) · MTD: ay başından bugüne · BP: bütçe · CRM: sadakat programı · OE: origin espresso · Food attach: içecek başına yiyecek oranı
A15: Food MO: yiyecek fire (mark-out) oranı · ASA: genel operasyon denetimi · PAP: kayıp önleme / çalışan güvence denetimi · RSA: gıda güvenliği denetimi
... A18: Renk kodu: mavi = girilen değer · sarı zemin = her ay seçilen hücre · siyah = formül · yeşil = başka sayfadan gelen değer

Sheet Genel_Tablo
A1: Dönem: | B1: P3 | D1: ="Bölge KPI Genel Tablo — "&B1 -> Bölge KPI Genel Tablo — P3
C2: SATIŞ | F2: P&L | H2: CRM | I2: PAKET SERVİS | L2: ÜRÜN KARMASI | O2: FİRE / ENVANTER | Q2: EKİP | T2: MİSAFİR | U2: DENETİM
A3: Hedef | E3: =Hedefler!$D$4&" "&TEXT(Hedefler!$E$4,"0.0%") -> ≥ 0.0% | G3: =Hedefler!$D$5&" "&TEXT(Hedefler!$E$5,"0.0%") -> ≥ 0.0% | H3: =Hedefler!$D$6&" "&TEXT(Hedefler!$E$6,"0.0%") -> ≥ 14.0% | I3: =Hedefler!$D$7&" "&TEXT(Hedefler!$E$7,"0.0%") -> ≤ 7.0% | J3: =Hedefler!$D$8&" "&TEXT(Hedefler!$E$8,"0.0%") -> ≥ 90.0% | L3: =Hedefler!$D$9&" "&TEXT(Hedefler!$E$9,"0.0%") -> ≥ 18.0% | N3: =Hedefler!$D$10&" "&TEXT(Hedefler!$E$10,"0.0%") -> ≥ 0.0% | O3: =Hedefler!$D$11&" "&TEXT(Hedefler!$E$11,"0.0%") -> ≤ 8.0% | P3: =Hedefler!$D$12&" "&TEXT(Hedefler!$E$12,"0.00%") -> ≥ -0.50% | Q3: =Hedefler!$D$13&" "&TEXT(Hedefler!$E$13,"0%") -> ≥ 95% | R3: =Hedefler!$D$14&" "&TEXT(Hedefler!$E$14,"0%") -> ≤ 50% | S3: =Hedefler!$D$15&" "&TEXT(Hedefler!$E$15,"0") -> ≥ 0 | T3: =Hedefler!$D$16&" "&TEXT(Hedefler!$E$16,"0.00") -> ≤ 0.30 | U3: =Hedefler!$D$17&" "&TEXT(Hedefler!$E$17,"0") -> ≥ 90 | V3: =Hedefler!$D$18&" "&TEXT(Hedefler!$E$18,"0") -> ≥ 85 | W3: =Hedefler!$D$19&" "&TEXT(Hedefler!$E$19,"0") -> ≥ 90
A4: Mağaza | B4: Format | C4: ADT | D4: Net Satış (TL) | E4: Satış Bütçe Sapması % | F4: Mağaza Katkısı (Line 12) TL | G4: Line 12 Bütçe Sapması % | H4: CRM Satış % | I4: Paket İptal % | J4: Platform Açıklık % | K4: Paket Satış Payı % | L4: Origin Espresso % | M4: Food Attach % | N4: Food Attach Geçen Yıla Fark | O4: Food Mark-out % | P4: Envanter Farkı % | Q4: Eğitim Tamamlama % | R4: Turnover (YTD) % | S4: Kahve Sohbeti Hedef Farkı | T4: Şikâyet / 1.000 İşlem | U4: ASA | V4: PAP | W4: RSA | X4: Performans Puanı | Y4: Sıra | Z4: P&L Sapma Açıklaması
A5: Mağaza A | B5: AVM | C5: =IFERROR(INDEX(Satis!$D:$D,MATCH($B$1&"|"&$A5,Satis!$A:$A,0)),"") -> 622 | D5: =IFERROR(INDEX(Satis!$F:$F,MATCH($B$1&"|"&$A5,Satis!$A:$A,0)),"") -> 2416806 | E5: =IFERROR(INDEX(Satis!$F:$F,MATCH($B$1&"|"&$A5,Satis!$A:$A,0))/INDEX(Satis!$G:$G,MATCH($B$1&"|"&$A5,Satis!$A:$A,0))-1,"") -> 0.019696016 | F5: =IFERROR(INDEX(PnL!$K:$K,MATCH($B$1&"|"&$A5,PnL!$A:$A,0)),"") -> 637710 | G5: =IFERROR((INDEX(PnL!$K:$K,MATCH($B$1&"|"&$A5,PnL!$A:$A,0))-INDEX(PnL!$L:$L,MATCH($B$1&"|"&$A5,PnL!$A:$A,0)))/ABS(INDEX(PnL!$L:$L,MATCH($B$1&"|"&$A5,PnL!$A:$A,0))),"") -> -0.072097896 | H5: =IFERROR(INDEX(CRM!$G:$G,MATCH($B$1&"|"&$A5,CRM!$A:$A,0))/INDEX(CRM!$F:$F,MATCH($B$1&"|"&$A5,CRM!$A:$A,0)),"") -> 0.16280469 | I5: =IFERROR((INDEX(Paket_Servis!$E:$E,MATCH($B$1&"|"&$A5,Paket_Servis!$A:$A,0))+INDEX(Paket_Servis!$G:$G,MATCH($B$1&"|"&$A5,Paket_Servis!$A:$A,0)))/(INDEX(Paket_Servis!$D:$D,MATCH($B$1&"|"&$A5,Paket_Servis!$A:$A,0))+INDEX(Paket_Servis!$F:$F,MATCH($B$1&"|"&$A5,Paket_Servis!$A:$A,0))),"") -> 0.051569507 | J5: =IFERROR(AVERAGE(INDEX(Paket_Servis!$H:$H,MATCH($B$1&"|"&$A5,Paket_Servis!$A:$A,0)),INDEX(Paket_Servis!$I:$I,MATCH($B$1&"|"&$A5,Paket_Servis!$A:$A,0))),"") -> 0.9465 | K5: =IFERROR(INDEX(Paket_Servis!$J:$J,MATCH($B$1&"|"&$A5,Paket_Servis!$A:$A,0)),"") -> 0.133 | L5: =IFERROR(INDEX(Urun_Karmasi!$E:$E,MATCH($B$1&"|"&$A5,Urun_Karmasi!$A:$A,0))/INDEX(Urun_Karmasi!$D:$D,MATCH($B$1&"|"&$A5,Urun_Karmasi!$A:$A,0)),"") -> 0.21713204 | M5: =IFERROR(INDEX(Urun_Karmasi!$G:$G,MATCH($B$1&"|"&$A5,Urun_Karmasi!$A:$A,0))/INDEX(Urun_Karmasi!$F:$F,MATCH($B$1&"|"&$A5,Urun_Karmasi!$A:$A,0)),"") -> 0.32085746 | N5: =IFERROR(M5-INDEX(Urun_Karmasi!$H:$H,MATCH($B$1&"|"&$A5,Urun_Karmasi!$A:$A,0)),"") -> 0.013857464 | O5: =IFERROR(INDEX(Fire_Envanter!$E:$E,MATCH($B$1&"|"&$A5,Fire_Envanter!$A:$A,0))/INDEX(Fire_Envanter!$D:$D,MATCH($B$1&"|"&$A5,Fire_Envanter!$A:$A,0)),"") -> 0.048608954 | P5: =IFERROR(INDEX(Fire_Envanter!$G:$G,MATCH($B$1&"|"&$A5,Fire_Envanter!$A:$A,0))/INDEX(Fire_Envanter!$F:$F,MATCH($B$1&"|"&$A5,Fire_Envanter!$A:$A,0)),"") -> -0.001436573 | Q5: =IFERROR(INDEX(Egitim!$E:$E,MATCH($B$1&"|"&$A5,Egitim!$A:$A,0))/INDEX(Egitim!$D:$D,MATCH($B$1&"|"&$A5,Egitim!$A:$A,0)),"") -> 1 | R5: =IFERROR(INDEX(Personel!$E:$E,MATCH($B$1&"|"&$A5,Personel!$A:$A,0))/INDEX(Personel!$D:$D,MATCH($B$1&"|"&$A5,Personel!$A:$A,0)),"") -> 0.125 | S5: =IFERROR(INDEX(Kahve_Sohbeti!$E:$E,MATCH($B$1&"|"&$A5,Kahve_Sohbeti!$A:$A,0))-INDEX(Kahve_Sohbeti!$D:$D,MATCH($B$1&"|"&$A5,Kahve_Sohbeti!$A:$A,0))*0.2*2,"") -> -2.4 | T5: =IFERROR(INDEX(Sikayet!$E:$E,MATCH($B$1&"|"&$A5,Sikayet!$A:$A,0))/INDEX(Sikayet!$D:$D,MATCH($B$1&"|"&$A5,Sikayet!$A:$A,0))*1000,"") -> 0.2593092 | U5: =IFERROR(INDEX(Denetim!$D:$D,MATCH($B$1&"|"&$A5,Denetim!$A:$A,0)),"") -> 98 | V5: =IFERROR(INDEX(Denetim!$E:$E,MATCH($B$1&"|"&$A5,Denetim!$A:$A,0)),"") -> 84 | W5: =IFERROR(INDEX(Denetim!$F:$F,MATCH($B$1&"|"&$A5,Denetim!$A:$A,0)),"") -> 99 | X5: =INDEX(Performans_Puani!$S:$S,ROW()) -> 78 | Y5: =IFERROR(RANK(X5,$X$5:$X$12),"") -> 1 | Z5: =IFERROR(INDEX(PnL!$M:$M,MATCH($B$1&"|"&$A5,PnL!$A:$A,0))&"","") -> Kira farkı sözleşme yenilemesinden; emlak ekibine iletildi.
A6: Mağaza B | B6: Cadde | C6: =IFERROR(INDEX(Satis!$D:$D,MATCH($B$1&"|"&$A6,Satis!$A:$A,0)),"") -> 454 | D6: =IFERROR(INDEX(Satis!$F:$F,MATCH($B$1&"|"&$A6,Satis!$A:$A,0)),"") -> 1823427 | E6: =IFERROR(INDEX(Satis!$F:$F,MATCH($B$1&"|"&$A6,Satis!$A:$A,0))/INDEX(Satis!$G:$G,MATCH($B$1&"|"&$A6,Satis!$A:$A,0))-1,"") -> -0.0021075064 | F6: =IFERROR(INDEX(PnL!$K:$K,MATCH($B$1&"|"&$A6,PnL!$A:$A,0)),"") -> 668874 | G6: =IFERROR((INDEX(PnL!$K:$K,MATCH($B$1&"|"&$A6,PnL!$A:$A,0))-INDEX(PnL!$L:$L,MATCH($B$1&"|"&$A6,PnL!$A:$A,0)))/ABS(INDEX(PnL!$L:$L,MATCH($B$1&"|"&$A6,PnL!$A:$A,0))),"") -> 0.057971633 | H6: =IFERROR(INDEX(CRM!$G:$G,MATCH($B$1&"|"&$A6,CRM!$A:$A,0))/INDEX(CRM!$F:$F,MATCH($B$1&"|"&$A6,CRM!$A:$A,0)),"") -> 0.18686644 | I6: =IFERROR((INDEX(Paket_Servis!$E:$E,MATCH($B$1&"|"&$A6,Paket_Servis!$A:$A,0))+INDEX(Paket_Servis!$G:$G,MATCH($B$1&"|"&$A6,Paket_Servis!$A:$A,0)))/(INDEX(Paket_Servis!$D:$D,MATCH($B$1&"|"&$A6,Paket_Servis!$A:$A,0))+INDEX(Paket_Servis!$F:$F,MATCH($B$1&"|"&$A6,Paket_Servis!$A:$A,0))),"") -> 0.047328244 | J6: =IFERROR(AVERAGE(INDEX(Paket_Servis!$H:$H,MATCH($B$1&"|"&$A6,Paket_Servis!$A:$A,0)),INDEX(Paket_Servis!$I:$I,MATCH($B$1&"|"&$A6,Paket_Servis!$A:$A,0))),"") -> 0.9155 | K6: =IFERROR(INDEX(Paket_Servis!$J:$J,MATCH($B$1&"|"&$A6,Paket_Servis!$A:$A,0)),"") -> 0.128 | L6: =IFERROR(INDEX(Urun_Karmasi!$E:$E,MATCH($B$1&"|"&$A6,Urun_Karmasi!$A:$A,0))/INDEX(Urun_Karmasi!$D:$D,MATCH($B$1&"|"&$A6,Urun_Karmasi!$A:$A,0)),"") -> 0.21174458 | M6: =IFERROR(INDEX(Urun_Karmasi!$G:$G,MATCH($B$1&"|"&$A6,Urun_Karmasi!$A:$A,0))/INDEX(Urun_Karmasi!$F:$F,MATCH($B$1&"|"&$A6,Urun_Karmasi!$A:$A,0)),"") -> 0.30528747 | N6: =IFERROR(M6-INDEX(Urun_Karmasi!$H:$H,MATCH($B$1&"|"&$A6,Urun_Karmasi!$A:$A,0)),"") -> 0.020287465 | O6: =IFERROR(INDEX(Fire_Envanter!$E:$E,MATCH($B$1&"|"&$A6,Fire_Envanter!$A:$A,0))/INDEX(Fire_Envanter!$D:$D,MATCH($B$1&"|"&$A6,Fire_Envanter!$A:$A,0)),"") -> 0.041124019 | P6: =IFERROR(INDEX(Fire_Envanter!$G:$G,MATCH($B$1&"|"&$A6,Fire_Envanter!$A:$A,0))/INDEX(Fire_Envanter!$F:$F,MATCH($B$1&"|"&$A6,Fire_Envanter!$A:$A,0)),"") -> -0.0084807683 | Q6: =IFERROR(INDEX(Egitim!$E:$E,MATCH($B$1&"|"&$A6,Egitim!$A:$A,0))/INDEX(Egitim!$D:$D,MATCH($B$1&"|"&$A6,Egitim!$A:$A,0)),"") -> 1 | R6: =IFERROR(INDEX(Personel!$E:$E,MATCH($B$1&"|"&$A6,Personel!$A:$A,0))/INDEX(Personel!$D:$D,MATCH($B$1&"|"&$A6,Personel!$A:$A,0)),"") -> 0 | S6: =IFERROR(INDEX(Kahve_Sohbeti!$E:$E,MATCH($B$1&"|"&$A6,Kahve_Sohbeti!$A:$A,0))-INDEX(Kahve_Sohbeti!$D:$D,MATCH($B$1&"|"&$A6,Kahve_Sohbeti!$A:$A,0))*0.2*2,"") -> 2.6 | T6: =IFERROR(INDEX(Sikayet!$E:$E,MATCH($B$1&"|"&$A6,Sikayet!$A:$A,0))/INDEX(Sikayet!$D:$D,MATCH($B$1&"|"&$A6,Sikayet!$A:$A,0))*1000,"") -> 0.71053006 | U6: =IFERROR(INDEX(Denetim!$D:$D,MATCH($B$1&"|"&$A6,Denetim!$A:$A,0)),"") -> 92 | V6: =IFERROR(INDEX(Denetim!$E:$E,MATCH($B$1&"|"&$A6,Denetim!$A:$A,0)),"") -> 90 | W6: =IFERROR(INDEX(Denetim!$F:$F,MATCH($B$1&"|"&$A6,Denetim!$A:$A,0)),"") -> 90 | X6: =INDEX(Performans_Puani!$S:$S,ROW()) -> 75 | Y6: =IFERROR(RANK(X6,$X$5:$X$12),"") -> 3 | Z6: =IFERROR(INDEX(PnL!$M:$M,MATCH($B$1&"|"&$A6,PnL!$A:$A,0))&"","") -> Kira farkı sözleşme yenilemesinden; emlak ekibine iletildi.
A7: Mağaza C | B7: Kampüs | C7: =IFERROR(INDEX(Satis!$D:$D,MATCH($B$1&"|"&$A7,Satis!$A:$A,0)),"") -> 379 | D7: =IFERROR(INDEX(Satis!$F:$F,MATCH($B$1&"|"&$A7,Satis!$A:$A,0)),"") -> 1403301 | E7: =IFERROR(INDEX(Satis!$F:$F,MATCH($B$1&"|"&$A7,Satis!$A:$A,0))/INDEX(Satis!$G:$G,MATCH($B$1&"|"&$A7,Satis!$A:$A,0))-1,"") -> -0.034469543 | F7: =IFERROR(INDEX(PnL!$K:$K,MATCH($B$1&"|"&$A7,PnL!$A:$A,0)),"") -> 447567 | G7: =IFERROR((INDEX(PnL!$K:$K,MATCH($B$1&"|"&$A7,PnL!$A:$A,0))-INDEX(PnL!$L:$L,MATCH($B$1&"|"&$A7,PnL!$A:$A,0)))/ABS(INDEX(PnL!$L:$L,MATCH($B$1&"|"&$A7,PnL!$A:$A,0))),"") -> 0.097322199 | H7: =IFERROR(INDEX(CRM!$G:$G,MATCH($B$1&"|"&$A7,CRM!$A:$A,0))/INDEX(CRM!$F:$F,MATCH($B$1&"|"&$A7,CRM!$A:$A,0)),"") -> 0.12964011 | I7: =IFERROR((INDEX(Paket_Servis!$E:$E,MATCH($B$1&"|"&$A7,Paket_Servis!$A:$A,0))+INDEX(Paket_Servis!$G:$G,MATCH($B$1&"|"&$A7,Paket_Servis!$A:$A,0)))/(INDEX(Paket_Servis!$D:$D,MATCH($B$1&"|"&$A7,Paket_Servis!$A:$A,0))+INDEX(Paket_Servis!$F:$F,MATCH($B$1&"|"&$A7,Paket_Servis!$A:$A,0))),"") -> 0.073849879 | J7: =IFERROR(AVERAGE(INDEX(Paket_Servis!$H:$H,MATCH($B$1&"|"&$A7,Paket_Servis!$A:$A,0)),INDEX(Paket_Servis!$I:$I,MATCH($B$1&"|"&$A7,Paket_Servis!$A:$A,0))),"") -> 0.879 | K7: =IFERROR(INDEX(Paket_Servis!$J:$J,MATCH($B$1&"|"&$A7,Paket_Servis!$A:$A,0)),"") -> 0.053 | L7: =IFERROR(INDEX(Urun_Karmasi!$E:$E,MATCH($B$1&"|"&$A7,Urun_Karmasi!$A:$A,0))/INDEX(Urun_Karmasi!$D:$D,MATCH($B$1&"|"&$A7,Urun_Karmasi!$A:$A,0)),"") -> 0.23039751 | M7: =IFERROR(INDEX(Urun_Karmasi!$G:$G,MATCH($B$1&"|"&$A7,Urun_Karmasi!$A:$A,0))/INDEX(Urun_Karmasi!$F:$F,MATCH($B$1&"|"&$A7,Urun_Karmasi!$A:$A,0)),"") -> 0.34357047 | N7: =IFERROR(M7-INDEX(Urun_Karmasi!$H:$H,MATCH($B$1&"|"&$A7,Urun_Karmasi!$A:$A,0)),"") -> -0.003429534 | O7: =IFERROR(INDEX(Fire_Envanter!$E:$E,MATCH($B$1&"|"&$A7,Fire_Envanter!$A:$A,0))/INDEX(Fire_Envanter!$D:$D,MATCH($B$1&"|"&$A7,Fire_Envanter!$A:$A,0)),"") -> 0.046392964 | P7: =IFERROR(INDEX(Fire_Envanter!$G:$G,MATCH($B$1&"|"&$A7,Fire_Envanter!$A:$A,0))/INDEX(Fire_Envanter!$F:$F,MATCH($B$1&"|"&$A7,Fire_Envanter!$A:$A,0)),"") -> -0.00014185604 | Q7: =IFERROR(INDEX(Egitim!$E:$E,MATCH($B$1&"|"&$A7,Egitim!$A:$A,0))/INDEX(Egitim!$D:$D,MATCH($B$1&"|"&$A7,Egitim!$A:$A,0)),"") -> 1 | R7: =IFERROR(INDEX(Personel!$E:$E,MATCH($B$1&"|"&$A7,Personel!$A:$A,0))/INDEX(Personel!$D:$D,MATCH($B$1&"|"&$A7,Personel!$A:$A,0)),"") -> 0.11111111 | S7: =IFERROR(INDEX(Kahve_Sohbeti!$E:$E,MATCH($B$1&"|"&$A7,Kahve_Sohbeti!$A:$A,0))-INDEX(Kahve_Sohbeti!$D:$D,MATCH($B$1&"|"&$A7,Kahve_Sohbeti!$A:$A,0))*0.2*2,"") -> 3.4 | T7: =IFERROR(INDEX(Sikayet!$E:$E,MATCH($B$1&"|"&$A7,Sikayet!$A:$A,0))/INDEX(Sikayet!$D:$D,MATCH($B$1&"|"&$A7,Sikayet!$A:$A,0))*1000,"") -> 0 | U7: =IFERROR(INDEX(Denetim!$D:$D,MATCH($B$1&"|"&$A7,Denetim!$A:$A,0)),"") -> 85 | V7: =IFERROR(INDEX(Denetim!$E:$E,MATCH($B$1&"|"&$A7,Denetim!$A:$A,0)),"") -> 95 | W7: =IFERROR(INDEX(Denetim!$F:$F,MATCH($B$1&"|"&$A7,Denetim!$A:$A,0)),"") -> 91 | X7: =INDEX(Performans_Puani!$S:$S,ROW()) -> 57 | Y7: =IFERROR(RANK(X7,$X$5:$X$12),"") -> 6 | Z7: =IFERROR(INDEX(PnL!$M:$M,MATCH($B$1&"|"&$A7,PnL!$A:$A,0))&"","")
A8: Mağaza D | B8: Havalimanı | C8: =IFERROR(INDEX(Satis!$D:$D,MATCH($B$1&"|"&$A8,Satis!$A:$A,0)),"") -> 773 | D8: =IFERROR(INDEX(Satis!$F:$F,MATCH($B$1&"|"&$A8,Satis!$A:$A,0)),"") -> 3217033 | E8: =IFERROR(INDEX(Satis!$F:$F,MATCH($B$1&"|"&$A8,Satis!$A:$A,0))/INDEX(Satis!$G:$G,MATCH($B$1&"|"&$A8,Satis!$A:$A,0))-1,"") -> 0.071317654 | F8: =IFERROR(INDEX(PnL!$K:$K,MATCH($B$1&"|"&$A8,PnL!$A:$A,0)),"") -> 1155158 | G8: =IFERROR((INDEX(PnL!$K:$K,MATCH($B$1&"|"&$A8,PnL!$A:$A,0))-INDEX(PnL!$L:$L,MATCH($B$1&"|"&$A8,PnL!$A:$A,0)))/ABS(INDEX(PnL!$L:$L,MATCH($B$1&"|"&$A8,PnL!$A:$A,0))),"") -> -0.090421758 | H8: =IFERROR(INDEX(CRM!$G:$G,MATCH($B$1&"|"&$A8,CRM!$A:$A,0))/INDEX(CRM!$F:$F,MATCH($B$1&"|"&$A8,CRM!$A:$A,0)),"") -> 0.11319812 | I8: =IFERROR((INDEX(Paket_Servis!$E:$E,MATCH($B$1&"|"&$A8,Paket_Servis!$A:$A,0))+INDEX(Paket_Servis!$G:$G,MATCH($B$1&"|"&$A8,Paket_Servis!$A:$A,0)))/(INDEX(Paket_Servis!$D:$D,MATCH($B$1&"|"&$A8,Paket_Servis!$A:$A,0))+INDEX(Paket_Servis!$F:$F,MATCH($B$1&"|"&$A8,Paket_Servis!$A:$A,0))),"") -> 0.054176072 | J8: =IFERROR(AVERAGE(INDEX(Paket_Servis!$H:$H,MATCH($B$1&"|"&$A8,Paket_Servis!$A:$A,0)),INDEX(Paket_Servis!$I:$I,MATCH($B$1&"|"&$A8,Paket_Servis!$A:$A,0))),"") -> 0.943 | K8: =IFERROR(INDEX(Paket_Servis!$J:$J,MATCH($B$1&"|"&$A8,Paket_Servis!$A:$A,0)),"") -> 0.118 | L8: =IFERROR(INDEX(Urun_Karmasi!$E:$E,MATCH($B$1&"|"&$A8,Urun_Karmasi!$A:$A,0))/INDEX(Urun_Karmasi!$D:$D,MATCH($B$1&"|"&$A8,Urun_Karmasi!$A:$A,0)),"") -> 0.15841817 | M8: =IFERROR(INDEX(Urun_Karmasi!$G:$G,MATCH($B$1&"|"&$A8,Urun_Karmasi!$A:$A,0))/INDEX(Urun_Karmasi!$F:$F,MATCH($B$1&"|"&$A8,Urun_Karmasi!$A:$A,0)),"") -> 0.33165252 | N8: =IFERROR(M8-INDEX(Urun_Karmasi!$H:$H,MATCH($B$1&"|"&$A8,Urun_Karmasi!$A:$A,0)),"") -> -0.018347475 | O8: =IFERROR(INDEX(Fire_Envanter!$E:$E,MATCH($B$1&"|"&$A8,Fire_Envanter!$A:$A,0))/INDEX(Fire_Envanter!$D:$D,MATCH($B$1&"|"&$A8,Fire_Envanter!$A:$A,0)),"") -> 0.059276207 | P8: =IFERROR(INDEX(Fire_Envanter!$G:$G,MATCH($B$1&"|"&$A8,Fire_Envanter!$A:$A,0))/INDEX(Fire_Envanter!$F:$F,MATCH($B$1&"|"&$A8,Fire_Envanter!$A:$A,0)),"") -> -0.0056291644 | Q8: =IFERROR(INDEX(Egitim!$E:$E,MATCH($B$1&"|"&$A8,Egitim!$A:$A,0))/INDEX(Egitim!$D:$D,MATCH($B$1&"|"&$A8,Egitim!$A:$A,0)),"") -> 0.94444444 | R8: =IFERROR(INDEX(Personel!$E:$E,MATCH($B$1&"|"&$A8,Personel!$A:$A,0))/INDEX(Personel!$D:$D,MATCH($B$1&"|"&$A8,Personel!$A:$A,0)),"") -> 0.21052632 | S8: =IFERROR(INDEX(Kahve_Sohbeti!$E:$E,MATCH($B$1&"|"&$A8,Kahve_Sohbeti!$A:$A,0))-INDEX(Kahve_Sohbeti!$D:$D,MATCH($B$1&"|"&$A8,Kahve_Sohbeti!$A:$A,0))*0.2*2,"") -> 3.4 | T8: =IFERROR(INDEX(Sikayet!$E:$E,MATCH($B$1&"|"&$A8,Sikayet!$A:$A,0))/INDEX(Sikayet!$D:$D,MATCH($B$1&"|"&$A8,Sikayet!$A:$A,0))*1000,"") -> 0.37557902 | U8: =IFERROR(INDEX(Denetim!$D:$D,MATCH($B$1&"|"&$A8,Denetim!$A:$A,0)),"") -> 89 | V8: =IFERROR(INDEX(Denetim!$E:$E,MATCH($B$1&"|"&$A8,Denetim!$A:$A,0)),"") -> 81 | W8: =IFERROR(INDEX(Denetim!$F:$F,MATCH($B$1&"|"&$A8,Denetim!$A:$A,0)),"") -> 86 | X8: =INDEX(Performans_Puani!$S:$S,ROW()) -> 41 | Y8: =IFERROR(RANK(X8,$X$5:$X$12),"") -> 7 | Z8: =IFERROR(INDEX(PnL!$M:$M,MATCH($B$1&"|"&$A8,PnL!$A:$A,0))&"","") -> Satış bütçenin altında kaldı; mağaza katkısı bundan etkilendi, diğer kalemler stabil.
A9: Mağaza E | B9: Otoyol | C9: =IFERROR(INDEX(Satis!$D:$D,MATCH($B$1&"|"&$A9,Satis!$A:$A,0)),"") -> 595 | D9: =IFERROR(INDEX(Satis!$F:$F,MATCH($B$1&"|"&$A9,Satis!$A:$A,0)),"") -> 2404306 | E9: =IFERROR(INDEX(Satis!$F:$F,MATCH($B$1&"|"&$A9,Satis!$A:$A,0))/INDEX(Satis!$G:$G,MATCH($B$1&"|"&$A9,Satis!$A:$A,0))-1,"") -> 0.072144252 | F9: =IFERROR(INDEX(PnL!$K:$K,MATCH($B$1&"|"&$A9,PnL!$A:$A,0)),"") -> 766862 | G9: =IFERROR((INDEX(PnL!$K:$K,MATCH($B$1&"|"&$A9,PnL!$A:$A,0))-INDEX(PnL!$L:$L,MATCH($B$1&"|"&$A9,PnL!$A:$A,0)))/ABS(INDEX(PnL!$L:$L,MATCH($B$1&"|"&$A9,PnL!$A:$A,0))),"") -> 0.066146334 | H9: =IFERROR(INDEX(CRM!$G:$G,MATCH($B$1&"|"&$A9,CRM!$A:$A,0))/INDEX(CRM!$F:$F,MATCH($B$1&"|"&$A9,CRM!$A:$A,0)),"") -> 0.12091533 | I9: =IFERROR((INDEX(Paket_Servis!$E:$E,MATCH($B$1&"|"&$A9,Paket_Servis!$A:$A,0))+INDEX(Paket_Servis!$G:$G,MATCH($B$1&"|"&$A9,Paket_Servis!$A:$A,0)))/(INDEX(Paket_Servis!$D:$D,MATCH($B$1&"|"&$A9,Paket_Servis!$A:$A,0))+INDEX(Paket_Servis!$F:$F,MATCH($B$1&"|"&$A9,Paket_Servis!$A:$A,0))),"") -> 0.052950076 | J9: =IFERROR(AVERAGE(INDEX(Paket_Servis!$H:$H,MATCH($B$1&"|"&$A9,Paket_Servis!$A:$A,0)),INDEX(Paket_Servis!$I:$I,MATCH($B$1&"|"&$A9,Paket_Servis!$A:$A,0))),"") -> 0.9015 | K9: =IFERROR(INDEX(Paket_Servis!$J:$J,MATCH($B$1&"|"&$A9,Paket_Servis!$A:$A,0)),"") -> 0.159 | L9: =IFERROR(INDEX(Urun_Karmasi!$E:$E,MATCH($B$1&"|"&$A9,Urun_Karmasi!$A:$A,0))/INDEX(Urun_Karmasi!$D:$D,MATCH($B$1&"|"&$A9,Urun_Karmasi!$A:$A,0)),"") -> 0.21196182 | M9: =IFERROR(INDEX(Urun_Karmasi!$G:$G,MATCH($B$1&"|"&$A9,Urun_Karmasi!$A:$A,0))/INDEX(Urun_Karmasi!$F:$F,MATCH($B$1&"|"&$A9,Urun_Karmasi!$A:$A,0)),"") -> 0.3071293 | N9: =IFERROR(M9-INDEX(Urun_Karmasi!$H:$H,MATCH($B$1&"|"&$A9,Urun_Karmasi!$A:$A,0)),"") -> -0.0088706967 | O9: =IFERROR(INDEX(Fire_Envanter!$E:$E,MATCH($B$1&"|"&$A9,Fire_Envanter!$A:$A,0))/INDEX(Fire_Envanter!$D:$D,MATCH($B$1&"|"&$A9,Fire_Envanter!$A:$A,0)),"") -> 0.069862725 | P9: =IFERROR(INDEX(Fire_Envanter!$G:$G,MATCH($B$1&"|"&$A9,Fire_Envanter!$A:$A,0))/INDEX(Fire_Envanter!$F:$F,MATCH($B$1&"|"&$A9,Fire_Envanter!$A:$A,0)),"") -> -0.0054445649 | Q9: =IFERROR(INDEX(Egitim!$E:$E,MATCH($B$1&"|"&$A9,Egitim!$A:$A,0))/INDEX(Egitim!$D:$D,MATCH($B$1&"|"&$A9,Egitim!$A:$A,0)),"") -> 0.88235294 | R9: =IFERROR(INDEX(Personel!$E:$E,MATCH($B$1&"|"&$A9,Personel!$A:$A,0))/INDEX(Personel!$D:$D,MATCH($B$1&"|"&$A9,Personel!$A:$A,0)),"") -> 0 | S9: =IFERROR(INDEX(Kahve_Sohbeti!$E:$E,MATCH($B$1&"|"&$A9,Kahve_Sohbeti!$A:$A,0))-INDEX(Kahve_Sohbeti!$D:$D,MATCH($B$1&"|"&$A9,Kahve_Sohbeti!$A:$A,0))*0.2*2,"") -> -1.2 | T9: =IFERROR(INDEX(Sikayet!$E:$E,MATCH($B$1&"|"&$A9,Sikayet!$A:$A,0))/INDEX(Sikayet!$D:$D,MATCH($B$1&"|"&$A9,Sikayet!$A:$A,0))*1000,"") -> 0.21686094 | U9: =IFERROR(INDEX(Denetim!$D:$D,MATCH($B$1&"|"&$A9,Denetim!$A:$A,0)),"") -> 91 | V9: =IFERROR(INDEX(Denetim!$E:$E,MATCH($B$1&"|"&$A9,Denetim!$A:$A,0)),"") -> 87 | W9: =IFERROR(INDEX(Denetim!$F:$F,MATCH($B$1&"|"&$A9,Denetim!$A:$A,0)),"") -> 88 | X9: =INDEX(Performans_Puani!$S:$S,ROW()) -> 67 | Y9: =IFERROR(RANK(X9,$X$5:$X$12),"") -> 4 | Z9: =IFERROR(INDEX(PnL!$M:$M,MATCH($B$1&"|"&$A9,PnL!$A:$A,0))&"","") -> Satış bütçenin altında kaldı; mağaza katkısı bundan etkilendi, diğer kalemler stabil.
A10: Mağaza F | B10: AVM | C10: =IFERROR(INDEX(Satis!$D:$D,MATCH($B$1&"|"&$A10,Satis!$A:$A,0)),"") -> 544 | D10: =IFERROR(INDEX(Satis!$F:$F,MATCH($B$1&"|"&$A10,Satis!$A:$A,0)),"") -> 1956055 | E10: =IFERROR(INDEX(Satis!$F:$F,MATCH($B$1&"|"&$A10,Satis!$A:$A,0))/INDEX(Satis!$G:$G,MATCH($B$1&"|"&$A10,Satis!$A:$A,0))-1,"") -> -0.016500802 | F10: =IFERROR(INDEX(PnL!$K:$K,MATCH($B$1&"|"&$A10,PnL!$A:$A,0)),"") -> 662937 | G10: =IFERROR((INDEX(PnL!$K:$K,MATCH($B$1&"|"&$A10,PnL!$A:$A,0))-INDEX(PnL!$L:$L,MATCH($B$1&"|"&$A10,PnL!$A:$A,0)))/ABS(INDEX(PnL!$L:$L,MATCH($B$1&"|"&$A10,PnL!$A:$A,0))),"") -> -0.027975842 | H10: =IFERROR(INDEX(CRM!$G:$G,MATCH($B$1&"|"&$A10,CRM!$A:$A,0))/INDEX(CRM!$F:$F,MATCH($B$1&"|"&$A10,CRM!$A:$A,0)),"") -> 0.14139093 | I10: =IFERROR((INDEX(Paket_Servis!$E:$E,MATCH($B$1&"|"&$A10,Paket_Servis!$A:$A,0))+INDEX(Paket_Servis!$G:$G,MATCH($B$1&"|"&$A10,Paket_Servis!$A:$A,0)))/(INDEX(Paket_Servis!$D:$D,MATCH($B$1&"|"&$A10,Paket_Servis!$A:$A,0))+INDEX(Paket_Servis!$F:$F,MATCH($B$1&"|"&$A10,Paket_Servis!$A:$A,0))),"") -> 0.077507599 | J10: =IFERROR(AVERAGE(INDEX(Paket_Servis!$H:$H,MATCH($B$1&"|"&$A10,Paket_Servis!$A:$A,0)),INDEX(Paket_Servis!$I:$I,MATCH($B$1&"|"&$A10,Paket_Servis!$A:$A,0))),"") -> 0.9555 | K10: =IFERROR(INDEX(Paket_Servis!$J:$J,MATCH($B$1&"|"&$A10,Paket_Servis!$A:$A,0)),"") -> 0.063 | L10: =IFERROR(INDEX(Urun_Karmasi!$E:$E,MATCH($B$1&"|"&$A10,Urun_Karmasi!$A:$A,0))/INDEX(Urun_Karmasi!$D:$D,MATCH($B$1&"|"&$A10,Urun_Karmasi!$A:$A,0)),"") -> 0.13572572 | M10: =IFERROR(INDEX(Urun_Karmasi!$G:$G,MATCH($B$1&"|"&$A10,Urun_Karmasi!$A:$A,0))/INDEX(Urun_Karmasi!$F:$F,MATCH($B$1&"|"&$A10,Urun_Karmasi!$A:$A,0)),"") -> 0.33814301 | N10: =IFERROR(M10-INDEX(Urun_Karmasi!$H:$H,MATCH($B$1&"|"&$A10,Urun_Karmasi!$A:$A,0)),"") -> -0.019856995 | O10: =IFERROR(INDEX(Fire_Envanter!$E:$E,MATCH($B$1&"|"&$A10,Fire_Envanter!$A:$A,0))/INDEX(Fire_Envanter!$D:$D,MATCH($B$1&"|"&$A10,Fire_Envanter!$A:$A,0)),"") -> 0.072544507 | P10: =IFERROR(INDEX(Fire_Envanter!$G:$G,MATCH($B$1&"|"&$A10,Fire_Envanter!$A:$A,0))/INDEX(Fire_Envanter!$F:$F,MATCH($B$1&"|"&$A10,Fire_Envanter!$A:$A,0)),"") -> -0.00087167932 | Q10: =IFERROR(INDEX(Egitim!$E:$E,MATCH($B$1&"|"&$A10,Egitim!$A:$A,0))/INDEX(Egitim!$D:$D,MATCH($B$1&"|"&$A10,Egitim!$A:$A,0)),"") -> 1 | R10: =IFERROR(INDEX(Personel!$E:$E,MATCH($B$1&"|"&$A10,Personel!$A:$A,0))/INDEX(Personel!$D:$D,MATCH($B$1&"|"&$A10,Personel!$A:$A,0)),"") -> 0.16666667 | S10: =IFERROR(INDEX(Kahve_Sohbeti!$E:$E,MATCH($B$1&"|"&$A10,Kahve_Sohbeti!$A:$A,0))-INDEX(Kahve_Sohbeti!$D:$D,MATCH($B$1&"|"&$A10,Kahve_Sohbeti!$A:$A,0))*0.2*2,"") -> 0.2 | T10: =IFERROR(INDEX(Sikayet!$E:$E,MATCH($B$1&"|"&$A10,Sikayet!$A:$A,0))/INDEX(Sikayet!$D:$D,MATCH($B$1&"|"&$A10,Sikayet!$A:$A,0))*1000,"") -> 0.4743833 | U10: =IFERROR(INDEX(Denetim!$D:$D,MATCH($B$1&"|"&$A10,Denetim!$A:$A,0)),"") -> 84 | V10: =IFERROR(INDEX(Denetim!$E:$E,MATCH($B$1&"|"&$A10,Denetim!$A:$A,0)),"") -> 83 | W10: =IFERROR(INDEX(Denetim!$F:$F,MATCH($B$1&"|"&$A10,Denetim!$A:$A,0)),"") -> 82 | X10: =INDEX(Performans_Puani!$S:$S,ROW()) -> 41 | Y10: =IFERROR(RANK(X10,$X$5:$X$12),"") -> 7 | Z10: =IFERROR(INDEX(PnL!$M:$M,MATCH($B$1&"|"&$A10,PnL!$A:$A,0))&"","")
A11: Mağaza G | B11: Cadde | C11: =IFERROR(INDEX(Satis!$D:$D,MATCH($B$1&"|"&$A11,Satis!$A:$A,0)),"") -> 383 | D11: =IFERROR(INDEX(Satis!$F:$F,MATCH($B$1&"|"&$A11,Satis!$A:$A,0)),"") -> 1263287 | E11: =IFERROR(INDEX(Satis!$F:$F,MATCH($B$1&"|"&$A11,Satis!$A:$A,0))/INDEX(Satis!$G:$G,MATCH($B$1&"|"&$A11,Satis!$A:$A,0))-1,"") -> 0.044781415 | F11: =IFERROR(INDEX(PnL!$K:$K,MATCH($B$1&"|"&$A11,PnL!$A:$A,0)),"") -> 479964 | G11: =IFERROR((INDEX(PnL!$K:$K,MATCH($B$1&"|"&$A11,PnL!$A:$A,0))-INDEX(PnL!$L:$L,MATCH($B$1&"|"&$A11,PnL!$A:$A,0)))/ABS(INDEX(PnL!$L:$L,MATCH($B$1&"|"&$A11,PnL!$A:$A,0))),"") -> 0.03674679 | H11: =IFERROR(INDEX(CRM!$G:$G,MATCH($B$1&"|"&$A11,CRM!$A:$A,0))/INDEX(CRM!$F:$F,MATCH($B$1&"|"&$A11,CRM!$A:$A,0)),"") -> 0.14842359 | I11: =IFERROR((INDEX(Paket_Servis!$E:$E,MATCH($B$1&"|"&$A11,Paket_Servis!$A:$A,0))+INDEX(Paket_Servis!$G:$G,MATCH($B$1&"|"&$A11,Paket_Servis!$A:$A,0)))/(INDEX(Paket_Servis!$D:$D,MATCH($B$1&"|"&$A11,Paket_Servis!$A:$A,0))+INDEX(Paket_Servis!$F:$F,MATCH($B$1&"|"&$A11,Paket_Servis!$A:$A,0))),"") -> 0.063647491 | J11: =IFERROR(AVERAGE(INDEX(Paket_Servis!$H:$H,MATCH($B$1&"|"&$A11,Paket_Servis!$A:$A,0)),INDEX(Paket_Servis!$I:$I,MATCH($B$1&"|"&$A11,Paket_Servis!$A:$A,0))),"") -> 0.9135 | K11: =IFERROR(INDEX(Paket_Servis!$J:$J,MATCH($B$1&"|"&$A11,Paket_Servis!$A:$A,0)),"") -> 0.085 | L11: =IFERROR(INDEX(Urun_Karmasi!$E:$E,MATCH($B$1&"|"&$A11,Urun_Karmasi!$A:$A,0))/INDEX(Urun_Karmasi!$D:$D,MATCH($B$1&"|"&$A11,Urun_Karmasi!$A:$A,0)),"") -> 0.23503055 | M11: =IFERROR(INDEX(Urun_Karmasi!$G:$G,MATCH($B$1&"|"&$A11,Urun_Karmasi!$A:$A,0))/INDEX(Urun_Karmasi!$F:$F,MATCH($B$1&"|"&$A11,Urun_Karmasi!$A:$A,0)),"") -> 0.32404548 | N11: =IFERROR(M11-INDEX(Urun_Karmasi!$H:$H,MATCH($B$1&"|"&$A11,Urun_Karmasi!$A:$A,0)),"") -> -0.02695452 | O11: =IFERROR(INDEX(Fire_Envanter!$E:$E,MATCH($B$1&"|"&$A11,Fire_Envanter!$A:$A,0))/INDEX(Fire_Envanter!$D:$D,MATCH($B$1&"|"&$A11,Fire_Envanter!$A:$A,0)),"") -> 0.047300837 | P11: =IFERROR(INDEX(Fire_Envanter!$G:$G,MATCH($B$1&"|"&$A11,Fire_Envanter!$A:$A,0))/INDEX(Fire_Envanter!$F:$F,MATCH($B$1&"|"&$A11,Fire_Envanter!$A:$A,0)),"") -> 0.0016648418 | Q11: =IFERROR(INDEX(Egitim!$E:$E,MATCH($B$1&"|"&$A11,Egitim!$A:$A,0))/INDEX(Egitim!$D:$D,MATCH($B$1&"|"&$A11,Egitim!$A:$A,0)),"") -> 0.91666667 | R11: =IFERROR(INDEX(Personel!$E:$E,MATCH($B$1&"|"&$A11,Personel!$A:$A,0))/INDEX(Personel!$D:$D,MATCH($B$1&"|"&$A11,Personel!$A:$A,0)),"") -> 0.5 | S11: =IFERROR(INDEX(Kahve_Sohbeti!$E:$E,MATCH($B$1&"|"&$A11,Kahve_Sohbeti!$A:$A,0))-INDEX(Kahve_Sohbeti!$D:$D,MATCH($B$1&"|"&$A11,Kahve_Sohbeti!$A:$A,0))*0.2*2,"") -> 2 | T11: =IFERROR(INDEX(Sikayet!$E:$E,MATCH($B$1&"|"&$A11,Sikayet!$A:$A,0))/INDEX(Sikayet!$D:$D,MATCH($B$1&"|"&$A11,Sikayet!$A:$A,0))*1000,"") -> 0.50534827 | U11: =IFERROR(INDEX(Denetim!$D:$D,MATCH($B$1&"|"&$A11,Denetim!$A:$A,0)),"") -> 95 | V11: =IFERROR(INDEX(Denetim!$E:$E,MATCH($B$1&"|"&$A11,Denetim!$A:$A,0)),"") -> 83 | W11: =IFERROR(INDEX(Denetim!$F:$F,MATCH($B$1&"|"&$A11,Denetim!$A:$A,0)),"") -> 87 | X11: =INDEX(Performans_Puani!$S:$S,ROW()) -> 78 | Y11: =IFERROR(RANK(X11,$X$5:$X$12),"") -> 1 | Z11: =IFERROR(INDEX(PnL!$M:$M,MATCH($B$1&"|"&$A11,PnL!$A:$A,0))&"","") -> Satış bütçenin altında kaldı; mağaza katkısı bundan etkilendi, diğer kalemler stabil.
A12: Mağaza H | B12: Drive-thru | C12: =IFERROR(INDEX(Satis!$D:$D,MATCH($B$1&"|"&$A12,Satis!$A:$A,0)),"") -> 530 | D12: =IFERROR(INDEX(Satis!$F:$F,MATCH($B$1&"|"&$A12,Satis!$A:$A,0)),"") -> 1822087 | E12: =IFERROR(INDEX(Satis!$F:$F,MATCH($B$1&"|"&$A12,Satis!$A:$A,0))/INDEX(Satis!$G:$G,MATCH($B$1&"|"&$A12,Satis!$A:$A,0))-1,"") -> -0.041558703 | F12: =IFERROR(INDEX(PnL!$K:$K,MATCH($B$1&"|"&$A12,PnL!$A:$A,0)),"") -> 580543 | G12: =IFERROR((INDEX(PnL!$K:$K,MATCH($B$1&"|"&$A12,PnL!$A:$A,0))-INDEX(PnL!$L:$L,MATCH($B$1&"|"&$A12,PnL!$A:$A,0)))/ABS(INDEX(PnL!$L:$L,MATCH($B$1&"|"&$A12,PnL!$A:$A,0))),"") -> 0.020923423 | H12: =IFERROR(INDEX(CRM!$G:$G,MATCH($B$1&"|"&$A12,CRM!$A:$A,0))/INDEX(CRM!$F:$F,MATCH($B$1&"|"&$A12,CRM!$A:$A,0)),"") -> 0.15482502 | I12: =IFERROR((INDEX(Paket_Servis!$E:$E,MATCH($B$1&"|"&$A12,Paket_Servis!$A:$A,0))+INDEX(Paket_Servis!$G:$G,MATCH($B$1&"|"&$A12,Paket_Servis!$A:$A,0)))/(INDEX(Paket_Servis!$D:$D,MATCH($B$1&"|"&$A12,Paket_Servis!$A:$A,0))+INDEX(Paket_Servis!$F:$F,MATCH($B$1&"|"&$A12,Paket_Servis!$A:$A,0))),"") -> 0.080338266 | J12: =IFERROR(AVERAGE(INDEX(Paket_Servis!$H:$H,MATCH($B$1&"|"&$A12,Paket_Servis!$A:$A,0)),INDEX(Paket_Servis!$I:$I,MATCH($B$1&"|"&$A12,Paket_Servis!$A:$A,0))),"") -> 0.9225 | K12: =IFERROR(INDEX(Paket_Servis!$J:$J,MATCH($B$1&"|"&$A12,Paket_Servis!$A:$A,0)),"") -> 0.104 | L12: =IFERROR(INDEX(Urun_Karmasi!$E:$E,MATCH($B$1&"|"&$A12,Urun_Karmasi!$A:$A,0))/INDEX(Urun_Karmasi!$D:$D,MATCH($B$1&"|"&$A12,Urun_Karmasi!$A:$A,0)),"") -> 0.20683815 | M12: =IFERROR(INDEX(Urun_Karmasi!$G:$G,MATCH($B$1&"|"&$A12,Urun_Karmasi!$A:$A,0))/INDEX(Urun_Karmasi!$F:$F,MATCH($B$1&"|"&$A12,Urun_Karmasi!$A:$A,0)),"") -> 0.32958004 | N12: =IFERROR(M12-INDEX(Urun_Karmasi!$H:$H,MATCH($B$1&"|"&$A12,Urun_Karmasi!$A:$A,0)),"") -> 0.018580037 | O12: =IFERROR(INDEX(Fire_Envanter!$E:$E,MATCH($B$1&"|"&$A12,Fire_Envanter!$A:$A,0))/INDEX(Fire_Envanter!$D:$D,MATCH($B$1&"|"&$A12,Fire_Envanter!$A:$A,0)),"") -> 0.066158196 | P12: =IFERROR(INDEX(Fire_Envanter!$G:$G,MATCH($B$1&"|"&$A12,Fire_Envanter!$A:$A,0))/INDEX(Fire_Envanter!$F:$F,MATCH($B$1&"|"&$A12,Fire_Envanter!$A:$A,0)),"") -> -0.0061599716 | Q12: =IFERROR(INDEX(Egitim!$E:$E,MATCH($B$1&"|"&$A12,Egitim!$A:$A,0))/INDEX(Egitim!$D:$D,MATCH($B$1&"|"&$A12,Egitim!$A:$A,0)),"") -> 1 | R12: =IFERROR(INDEX(Personel!$E:$E,MATCH($B$1&"|"&$A12,Personel!$A:$A,0))/INDEX(Personel!$D:$D,MATCH($B$1&"|"&$A12,Personel!$A:$A,0)),"") -> 0.36363636 | S12: =IFERROR(INDEX(Kahve_Sohbeti!$E:$E,MATCH($B$1&"|"&$A12,Kahve_Sohbeti!$A:$A,0))-INDEX(Kahve_Sohbeti!$D:$D,MATCH($B$1&"|"&$A12,Kahve_Sohbeti!$A:$A,0))*0.2*2,"") -> -0.4 | T12: =IFERROR(INDEX(Sikayet!$E:$E,MATCH($B$1&"|"&$A12,Sikayet!$A:$A,0))/INDEX(Sikayet!$D:$D,MATCH($B$1&"|"&$A12,Sikayet!$A:$A,0))*1000,"") -> 0.48691418 | U12: =IFERROR(INDEX(Denetim!$D:$D,MATCH($B$1&"|"&$A12,Denetim!$A:$A,0)),"") -> 84 | V12: =IFERROR(INDEX(Denetim!$E:$E,MATCH($B$1&"|"&$A12,Denetim!$A:$A,0)),"") -> 96 | W12: =IFERROR(INDEX(Denetim!$F:$F,MATCH($B$1&"|"&$A12,Denetim!$A:$A,0)),"") -> 98 | X12: =INDEX(Performans_Puani!$S:$S,ROW()) -> 62 | Y12: =IFERROR(RANK(X12,$X$5:$X$12),"") -> 5 | Z12: =IFERROR(INDEX(PnL!$M:$M,MATCH($B$1&"|"&$A12,PnL!$A:$A,0))&"","") -> Kira farkı sözleşme yenilemesinden; emlak ekibine iletildi.
A13: BÖLGE | C13: =SUM(C5:C12) -> 4280 | D13: =SUM(D5:D12) -> 16306302 | E13: =IFERROR(SUMIFS(Satis!$F:$F,Satis!$B:$B,$B$1)/SUMIFS(Satis!$G:$G,Satis!$B:$B,$B$1)-1,"") -> 0.019443082 | F13: =SUM(F5:F12) -> 5399615 | G13: =IFERROR((SUMIFS(PnL!$K:$K,PnL!$B:$B,$B$1)-SUMIFS(PnL!$L:$L,PnL!$B:$B,$B$1))/ABS(SUMIFS(PnL!$L:$L,PnL!$B:$B,$B$1)),"") -> -0.0056408126 | H13: =IFERROR(AVERAGE(H5:H12),"") -> 0.14475803 | I13: =IFERROR(AVERAGE(I5:I12),"") -> 0.062670892 | J13: =IFERROR(AVERAGE(J5:J12),"") -> 0.922125 | K13: =IFERROR(AVERAGE(K5:K12),"") -> 0.105375 | L13: =IFERROR(AVERAGE(L5:L12),"") -> 0.20090607 | M13: =IFERROR(AVERAGE(M5:M12),"") -> 0.32503322 | N13: =IFERROR(AVERAGE(N5:N12),"") -> -0.0030917819 | O13: =IFERROR(AVERAGE(O5:O12),"") -> 0.056408551 | ... R13: =IFERROR(AVERAGE(R5:R12),"") -> 0.18461756 | S13: =SUM(S5:S12) -> 7.6 | T13: =IFERROR(AVERAGE(T5:T12),"") -> 0.37861562 | U13: =IFERROR(AVERAGE(U5:U12),"") -> 89.75 | V13: =IFERROR(AVERAGE(V5:V12),"") -> 87.375 | W13: =IFERROR(AVERAGE(W5:W12),"") -> 90.125 | X13: =IFERROR(AVERAGE(X5:X12),"") -> 62.375
A14: Bölge satırında oranlar mağaza ortalamasıdır. Yeşil: hedef tuttu · Kırmızı: tutmadı. Puan: 80 ve üzeri yeşil, 60 altı kırmızı.

Sheet Performans_Puani
A1: ="Performans Puanı — "&Genel_Tablo!B1 -> Performans Puanı — P3
A2: Her gösterge hedefi tuttuysa Hedefler sayfasındaki katsayı kadar puan verir. Toplam 100 üzerindendir. Veri yoksa gösterge puansız kalır.
A3: Katsayı | B3: =Hedefler!F4 -> 15 | C3: =Hedefler!F5 -> 15 | D3: =Hedefler!F6 -> 8 | E3: =Hedefler!F7 -> 5 | F3: =Hedefler!F8 -> 5 | G3: =Hedefler!F9 -> 4 | H3: =Hedefler!F10 -> 6 | I3: =Hedefler!F11 -> 6 | J3: =Hedefler!F12 -> 6 | K3: =Hedefler!F13 -> 6 | L3: =Hedefler!F14 -> 6 | M3: =Hedefler!F15 -> 4 | N3: =Hedefler!F16 -> 4 | O3: =Hedefler!F17 -> 4 | P3: =Hedefler!F18 -> 3 | Q3: =Hedefler!F19 -> 3
A4: Mağaza | B4: SAT | C4: L12 | D4: CRM | E4: IPT | F4: ACK | G4: OE | H4: FAF | I4: FMO | J4: ENV | K4: EGT | L4: TRN | M4: KSF | N4: CFS | O4: ASA | P4: PAP | Q4: RSA | S4: Puan
A5: =Genel_Tablo!A5 -> Mağaza A | B5: =IF(Genel_Tablo!E5="","",IF(IF(Hedefler!$D$4="≥",Genel_Tablo!E5>=Hedefler!$E$4,Genel_Tablo!E5<=Hedefler!$E$4),Hedefler!$F$4,0)) -> 15 | C5: =IF(Genel_Tablo!G5="","",IF(IF(Hedefler!$D$5="≥",Genel_Tablo!G5>=Hedefler!$E$5,Genel_Tablo!G5<=Hedefler!$E$5),Hedefler!$F$5,0)) -> 0 | D5: =IF(Genel_Tablo!H5="","",IF(IF(Hedefler!$D$6="≥",Genel_Tablo!H5>=Hedefler!$E$6,Genel_Tablo!H5<=Hedefler!$E$6),Hedefler!$F$6,0)) -> 8 | E5: =IF(Genel_Tablo!I5="","",IF(IF(Hedefler!$D$7="≥",Genel_Tablo!I5>=Hedefler!$E$7,Genel_Tablo!I5<=Hedefler!$E$7),Hedefler!$F$7,0)) -> 5 | F5: =IF(Genel_Tablo!J5="","",IF(IF(Hedefler!$D$8="≥",Genel_Tablo!J5>=Hedefler!$E$8,Genel_Tablo!J5<=Hedefler!$E$8),Hedefler!$F$8,0)) -> 5 | G5: =IF(Genel_Tablo!L5="","",IF(IF(Hedefler!$D$9="≥",Genel_Tablo!L5>=Hedefler!$E$9,Genel_Tablo!L5<=Hedefler!$E$9),Hedefler!$F$9,0)) -> 4 | H5: =IF(Genel_Tablo!N5="","",IF(IF(Hedefler!$D$10="≥",Genel_Tablo!N5>=Hedefler!$E$10,Genel_Tablo!N5<=Hedefler!$E$10),Hedefler!$F$10,0)) -> 6 | I5: =IF(Genel_Tablo!O5="","",IF(IF(Hedefler!$D$11="≥",Genel_Tablo!O5>=Hedefler!$E$11,Genel_Tablo!O5<=Hedefler!$E$11),Hedefler!$F$11,0)) -> 6 | J5: =IF(Genel_Tablo!P5="","",IF(IF(Hedefler!$D$12="≥",Genel_Tablo!P5>=Hedefler!$E$12,Genel_Tablo!P5<=Hedefler!$E$12),Hedefler!$F$12,0)) -> 6 | K5: =IF(Genel_Tablo!Q5="","",IF(IF(Hedefler!$D$13="≥",Genel_Tablo!Q5>=Hedefler!$E$13,Genel_Tablo!Q5<=Hedefler!$E$13),Hedefler!$F$13,0)) -> 6 | L5: =IF(Genel_Tablo!R5="","",IF(IF(Hedefler!$D$14="≥",Genel_Tablo!R5>=Hedefler!$E$14,Genel_Tablo!R5<=Hedefler!$E$14),Hedefler!$F$14,0)) -> 6 | M5: =IF(Genel_Tablo!S5="","",IF(IF(Hedefler!$D$15="≥",Genel_Tablo!S5>=Hedefler!$E$15,Genel_Tablo!S5<=Hedefler!$E$15),Hedefler!$F$15,0)) -> 0 | N5: =IF(Genel_Tablo!T5="","",IF(IF(Hedefler!$D$16="≥",Genel_Tablo!T5>=Hedefler!$E$16,Genel_Tablo!T5<=Hedefler!$E$16),Hedefler!$F$16,0)) -> 4 | O5: =IF(Genel_Tablo!U5="","",IF(IF(Hedefler!$D$17="≥",Genel_Tablo!U5>=Hedefler!$E$17,Genel_Tablo!U5<=Hedefler!$E$17),Hedefler!$F$17,0)) -> 4 | P5: =IF(Genel_Tablo!V5="","",IF(IF(Hedefler!$D$18="≥",Genel_Tablo!V5>=Hedefler!$E$18,Genel_Tablo!V5<=Hedefler!$E$18),Hedefler!$F$18,0)) -> 0 | Q5: =IF(Genel_Tablo!W5="","",IF(IF(Hedefler!$D$19="≥",Genel_Tablo!W5>=Hedefler!$E$19,Genel_Tablo!W5<=Hedefler!$E$19),Hedefler!$F$19,0)) -> 3 | S5: =SUM(B5:Q5) -> 78
A6: =Genel_Tablo!A6 -> Mağaza B | B6: =IF(Genel_Tablo!E6="","",IF(IF(Hedefler!$D$4="≥",Genel_Tablo!E6>=Hedefler!$E$4,Genel_Tablo!E6<=Hedefler!$E$4),Hedefler!$F$4,0)) -> 0 | C6: =IF(Genel_Tablo!G6="","",IF(IF(Hedefler!$D$5="≥",Genel_Tablo!G6>=Hedefler!$E$5,Genel_Tablo!G6<=Hedefler!$E$5),Hedefler!$F$5,0)) -> 15 | D6: =IF(Genel_Tablo!H6="","",IF(IF(Hedefler!$D$6="≥",Genel_Tablo!H6>=Hedefler!$E$6,Genel_Tablo!H6<=Hedefler!$E$6),Hedefler!$F$6,0)) -> 8 | E6: =IF(Genel_Tablo!I6="","",IF(IF(Hedefler!$D$7="≥",Genel_Tablo!I6>=Hedefler!$E$7,Genel_Tablo!I6<=Hedefler!$E$7),Hedefler!$F$7,0)) -> 5 | F6: =IF(Genel_Tablo!J6="","",IF(IF(Hedefler!$D$8="≥",Genel_Tablo!J6>=Hedefler!$E$8,Genel_Tablo!J6<=Hedefler!$E$8),Hedefler!$F$8,0)) -> 5 | G6: =IF(Genel_Tablo!L6="","",IF(IF(Hedefler!$D$9="≥",Genel_Tablo!L6>=Hedefler!$E$9,Genel_Tablo!L6<=Hedefler!$E$9),Hedefler!$F$9,0)) -> 4 | H6: =IF(Genel_Tablo!N6="","",IF(IF(Hedefler!$D$10="≥",Genel_Tablo!N6>=Hedefler!$E$10,Genel_Tablo!N6<=Hedefler!$E$10),Hedefler!$F$10,0)) -> 6 | I6: =IF(Genel_Tablo!O6="","",IF(IF(Hedefler!$D$11="≥",Genel_Tablo!O6>=Hedefler!$E$11,Genel_Tablo!O6<=Hedefler!$E$11),Hedefler!$F$11,0)) -> 6 | J6: =IF(Genel_Tablo!P6="","",IF(IF(Hedefler!$D$12="≥",Genel_Tablo!P6>=Hedefler!$E$12,Genel_Tablo!P6<=Hedefler!$E$12),Hedefler!$F$12,0)) -> 0 | K6: =IF(Genel_Tablo!Q6="","",IF(IF(Hedefler!$D$13="≥",Genel_Tablo!Q6>=Hedefler!$E$13,Genel_Tablo!Q6<=Hedefler!$E$13),Hedefler!$F$13,0)) -> 6 | L6: =IF(Genel_Tablo!R6="","",IF(IF(Hedefler!$D$14="≥",Genel_Tablo!R6>=Hedefler!$E$14,Genel_Tablo!R6<=Hedefler!$E$14),Hedefler!$F$14,0)) -> 6 | M6: =IF(Genel_Tablo!S6="","",IF(IF(Hedefler!$D$15="≥",Genel_Tablo!S6>=Hedefler!$E$15,Genel_Tablo!S6<=Hedefler!$E$15),Hedefler!$F$15,0)) -> 4 | N6: =IF(Genel_Tablo!T6="","",IF(IF(Hedefler!$D$16="≥",Genel_Tablo!T6>=Hedefler!$E$16,Genel_Tablo!T6<=Hedefler!$E$16),Hedefler!$F$16,0)) -> 0 | O6: =IF(Genel_Tablo!U6="","",IF(IF(Hedefler!$D$17="≥",Genel_Tablo!U6>=Hedefler!$E$17,Genel_Tablo!U6<=Hedefler!$E$17),Hedefler!$F$17,0)) -> 4 | P6: =IF(Genel_Tablo!V6="","",IF(IF(Hedefler!$D$18="≥",Genel_Tablo!V6>=Hedefler!$E$18,Genel_Tablo!V6<=Hedefler!$E$18),Hedefler!$F$18,0)) -> 3 | Q6: =IF(Genel_Tablo!W6="","",IF(IF(Hedefler!$D$19="≥",Genel_Tablo!W6>=Hedefler!$E$19,Genel_Tablo!W6<=Hedefler!$E$19),Hedefler!$F$19,0)) -> 3 | S6: =SUM(B6:Q6) -> 75
A7: =Genel_Tablo!A7 -> Mağaza C | B7: =IF(Genel_Tablo!E7="","",IF(IF(Hedefler!$D$4="≥",Genel_Tablo!E7>=Hedefler!$E$4,Genel_Tablo!E7<=Hedefler!$E$4),Hedefler!$F$4,0)) -> 0 | C7: =IF(Genel_Tablo!G7="","",IF(IF(Hedefler!$D$5="≥",Genel_Tablo!G7>=Hedefler!$E$5,Genel_Tablo!G7<=Hedefler!$E$5),Hedefler!$F$5,0)) -> 15 | D7: =IF(Genel_Tablo!H7="","",IF(IF(Hedefler!$D$6="≥",Genel_Tablo!H7>=Hedefler!$E$6,Genel_Tablo!H7<=Hedefler!$E$6),Hedefler!$F$6,0)) -> 0 | E7: =IF(Genel_Tablo!I7="","",IF(IF(Hedefler!$D$7="≥",Genel_Tablo!I7>=Hedefler!$E$7,Genel_Tablo!I7<=Hedefler!$E$7),Hedefler!$F$7,0)) -> 0 | F7: =IF(Genel_Tablo!J7="","",IF(IF(Hedefler!$D$8="≥",Genel_Tablo!J7>=Hedefler!$E$8,Genel_Tablo!J7<=Hedefler!$E$8),Hedefler!$F$8,0)) -> 0 | G7: =IF(Genel_Tablo!L7="","",IF(IF(Hedefler!$D$9="≥",Genel_Tablo!L7>=Hedefler!$E$9,Genel_Tablo!L7<=Hedefler!$E$9),Hedefler!$F$9,0)) -> 4 | H7: =IF(Genel_Tablo!N7="","",IF(IF(Hedefler!$D$10="≥",Genel_Tablo!N7>=Hedefler!$E$10,Genel_Tablo!N7<=Hedefler!$E$10),Hedefler!$F$10,0)) -> 0 | I7: =IF(Genel_Tablo!O7="","",IF(IF(Hedefler!$D$11="≥",Genel_Tablo!O7>=Hedefler!$E$11,Genel_Tablo!O7<=Hedefler!$E$11),Hedefler!$F$11,0)) -> 6 | J7: =IF(Genel_Tablo!P7="","",IF(IF(Hedefler!$D$12="≥",Genel_Tablo!P7>=Hedefler!$E$12,Genel_Tablo!P7<=Hedefler!$E$12),Hedefler!$F$12,0)) -> 6 | K7: =IF(Genel_Tablo!Q7="","",IF(IF(Hedefler!$D$13="≥",Genel_Tablo!Q7>=Hedefler!$E$13,Genel_Tablo!Q7<=Hedefler!$E$13),Hedefler!$F$13,0)) -> 6 | L7: =IF(Genel_Tablo!R7="","",IF(IF(Hedefler!$D$14="≥",Genel_Tablo!R7>=Hedefler!$E$14,Genel_Tablo!R7<=Hedefler!$E$14),Hedefler!$F$14,0)) -> 6 | M7: =IF(Genel_Tablo!S7="","",IF(IF(Hedefler!$D$15="≥",Genel_Tablo!S7>=Hedefler!$E$15,Genel_Tablo!S7<=Hedefler!$E$15),Hedefler!$F$15,0)) -> 4 | N7: =IF(Genel_Tablo!T7="","",IF(IF(Hedefler!$D$16="≥",Genel_Tablo!T7>=Hedefler!$E$16,Genel_Tablo!T7<=Hedefler!$E$16),Hedefler!$F$16,0)) -> 4 | O7: =IF(Genel_Tablo!U7="","",IF(IF(Hedefler!$D$17="≥",Genel_Tablo!U7>=Hedefler!$E$17,Genel_Tablo!U7<=Hedefler!$E$17),Hedefler!$F$17,0)) -> 0 | P7: =IF(Genel_Tablo!V7="","",IF(IF(Hedefler!$D$18="≥",Genel_Tablo!V7>=Hedefler!$E$18,Genel_Tablo!V7<=Hedefler!$E$18),Hedefler!$F$18,0)) -> 3 | Q7: =IF(Genel_Tablo!W7="","",IF(IF(Hedefler!$D$19="≥",Genel_Tablo!W7>=Hedefler!$E$19,Genel_Tablo!W7<=Hedefler!$E$19),Hedefler!$F$19,0)) -> 3 | S7: =SUM(B7:Q7) -> 57
A8: =Genel_Tablo!A8 -> Mağaza D | B8: =IF(Genel_Tablo!E8="","",IF(IF(Hedefler!$D$4="≥",Genel_Tablo!E8>=Hedefler!$E$4,Genel_Tablo!E8<=Hedefler!$E$4),Hedefler!$F$4,0)) -> 15 | C8: =IF(Genel_Tablo!G8="","",IF(IF(Hedefler!$D$5="≥",Genel_Tablo!G8>=Hedefler!$E$5,Genel_Tablo!G8<=Hedefler!$E$5),Hedefler!$F$5,0)) -> 0 | D8: =IF(Genel_Tablo!H8="","",IF(IF(Hedefler!$D$6="≥",Genel_Tablo!H8>=Hedefler!$E$6,Genel_Tablo!H8<=Hedefler!$E$6),Hedefler!$F$6,0)) -> 0 | E8: =IF(Genel_Tablo!I8="","",IF(IF(Hedefler!$D$7="≥",Genel_Tablo!I8>=Hedefler!$E$7,Genel_Tablo!I8<=Hedefler!$E$7),Hedefler!$F$7,0)) -> 5 | F8: =IF(Genel_Tablo!J8="","",IF(IF(Hedefler!$D$8="≥",Genel_Tablo!J8>=Hedefler!$E$8,Genel_Tablo!J8<=Hedefler!$E$8),Hedefler!$F$8,0)) -> 5 | G8: =IF(Genel_Tablo!L8="","",IF(IF(Hedefler!$D$9="≥",Genel_Tablo!L8>=Hedefler!$E$9,Genel_Tablo!L8<=Hedefler!$E$9),Hedefler!$F$9,0)) -> 0 | H8: =IF(Genel_Tablo!N8="","",IF(IF(Hedefler!$D$10="≥",Genel_Tablo!N8>=Hedefler!$E$10,Genel_Tablo!N8<=Hedefler!$E$10),Hedefler!$F$10,0)) -> 0 | I8: =IF(Genel_Tablo!O8="","",IF(IF(Hedefler!$D$11="≥",Genel_Tablo!O8>=Hedefler!$E$11,Genel_Tablo!O8<=Hedefler!$E$11),Hedefler!$F$11,0)) -> 6 | J8: =IF(Genel_Tablo!P8="","",IF(IF(Hedefler!$D$12="≥",Genel_Tablo!P8>=Hedefler!$E$12,Genel_Tablo!P8<=Hedefler!$E$12),Hedefler!$F$12,0)) -> 0 | K8: =IF(Genel_Tablo!Q8="","",IF(IF(Hedefler!$D$13="≥",Genel_Tablo!Q8>=Hedefler!$E$13,Genel_Tablo!Q8<=Hedefler!$E$13),Hedefler!$F$13,0)) -> 0 | L8: =IF(Genel_Tablo!R8="","",IF(IF(Hedefler!$D$14="≥",Genel_Tablo!R8>=Hedefler!$E$14,Genel_Tablo!R8<=Hedefler!$E$14),Hedefler!$F$14,0)) -> 6 | M8: =IF(Genel_Tablo!S8="","",IF(IF(Hedefler!$D$15="≥",Genel_Tablo!S8>=Hedefler!$E$15,Genel_Tablo!S8<=Hedefler!$E$15),Hedefler!$F$15,0)) -> 4 | N8: =IF(Genel_Tablo!T8="","",IF(IF(Hedefler!$D$16="≥",Genel_Tablo!T8>=Hedefler!$E$16,Genel_Tablo!T8<=Hedefler!$E$16),Hedefler!$F$16,0)) -> 0 | O8: =IF(Genel_Tablo!U8="","",IF(IF(Hedefler!$D$17="≥",Genel_Tablo!U8>=Hedefler!$E$17,Genel_Tablo!U8<=Hedefler!$E$17),Hedefler!$F$17,0)) -> 0 | P8: =IF(Genel_Tablo!V8="","",IF(IF(Hedefler!$D$18="≥",Genel_Tablo!V8>=Hedefler!$E$18,Genel_Tablo!V8<=Hedefler!$E$18),Hedefler!$F$18,0)) -> 0 | Q8: =IF(Genel_Tablo!W8="","",IF(IF(Hedefler!$D$19="≥",Genel_Tablo!W8>=Hedefler!$E$19,Genel_Tablo!W8<=Hedefler!$E$19),Hedefler!$F$19,0)) -> 0 | S8: =SUM(B8:Q8) -> 41
A9: =Genel_Tablo!A9 -> Mağaza E | B9: =IF(Genel_Tablo!E9="","",IF(IF(Hedefler!$D$4="≥",Genel_Tablo!E9>=Hedefler!$E$4,Genel_Tablo!E9<=Hedefler!$E$4),Hedefler!$F$4,0)) -> 15 | C9: =IF(Genel_Tablo!G9="","",IF(IF(Hedefler!$D$5="≥",Genel_Tablo!G9>=Hedefler!$E$5,Genel_Tablo!G9<=Hedefler!$E$5),Hedefler!$F$5,0)) -> 15 | D9: =IF(Genel_Tablo!H9="","",IF(IF(Hedefler!$D$6="≥",Genel_Tablo!H9>=Hedefler!$E$6,Genel_Tablo!H9<=Hedefler!$E$6),Hedefler!$F$6,0)) -> 0 | E9: =IF(Genel_Tablo!I9="","",IF(IF(Hedefler!$D$7="≥",Genel_Tablo!I9>=Hedefler!$E$7,Genel_Tablo!I9<=Hedefler!$E$7),Hedefler!$F$7,0)) -> 5 | F9: =IF(Genel_Tablo!J9="","",IF(IF(Hedefler!$D$8="≥",Genel_Tablo!J9>=Hedefler!$E$8,Genel_Tablo!J9<=Hedefler!$E$8),Hedefler!$F$8,0)) -> 5 | G9: =IF(Genel_Tablo!L9="","",IF(IF(Hedefler!$D$9="≥",Genel_Tablo!L9>=Hedefler!$E$9,Genel_Tablo!L9<=Hedefler!$E$9),Hedefler!$F$9,0)) -> 4 | H9: =IF(Genel_Tablo!N9="","",IF(IF(Hedefler!$D$10="≥",Genel_Tablo!N9>=Hedefler!$E$10,Genel_Tablo!N9<=Hedefler!$E$10),Hedefler!$F$10,0)) -> 0 | I9: =IF(Genel_Tablo!O9="","",IF(IF(Hedefler!$D$11="≥",Genel_Tablo!O9>=Hedefler!$E$11,Genel_Tablo!O9<=Hedefler!$E$11),Hedefler!$F$11,0)) -> 6 | J9: =IF(Genel_Tablo!P9="","",IF(IF(Hedefler!$D$12="≥",Genel_Tablo!P9>=Hedefler!$E$12,Genel_Tablo!P9<=Hedefler!$E$12),Hedefler!$F$12,0)) -> 0 | K9: =IF(Genel_Tablo!Q9="","",IF(IF(Hedefler!$D$13="≥",Genel_Tablo!Q9>=Hedefler!$E$13,Genel_Tablo!Q9<=Hedefler!$E$13),Hedefler!$F$13,0)) -> 0 | L9: =IF(Genel_Tablo!R9="","",IF(IF(Hedefler!$D$14="≥",Genel_Tablo!R9>=Hedefler!$E$14,Genel_Tablo!R9<=Hedefler!$E$14),Hedefler!$F$14,0)) -> 6 | M9: =IF(Genel_Tablo!S9="","",IF(IF(Hedefler!$D$15="≥",Genel_Tablo!S9>=Hedefler!$E$15,Genel_Tablo!S9<=Hedefler!$E$15),Hedefler!$F$15,0)) -> 0 | N9: =IF(Genel_Tablo!T9="","",IF(IF(Hedefler!$D$16="≥",Genel_Tablo!T9>=Hedefler!$E$16,Genel_Tablo!T9<=Hedefler!$E$16),Hedefler!$F$16,0)) -> 4 | O9: =IF(Genel_Tablo!U9="","",IF(IF(Hedefler!$D$17="≥",Genel_Tablo!U9>=Hedefler!$E$17,Genel_Tablo!U9<=Hedefler!$E$17),Hedefler!$F$17,0)) -> 4 | P9: =IF(Genel_Tablo!V9="","",IF(IF(Hedefler!$D$18="≥",Genel_Tablo!V9>=Hedefler!$E$18,Genel_Tablo!V9<=Hedefler!$E$18),Hedefler!$F$18,0)) -> 3 | Q9: =IF(Genel_Tablo!W9="","",IF(IF(Hedefler!$D$19="≥",Genel_Tablo!W9>=Hedefler!$E$19,Genel_Tablo!W9<=Hedefler!$E$19),Hedefler!$F$19,0)) -> 0 | S9: =SUM(B9:Q9) -> 67
A10: =Genel_Tablo!A10 -> Mağaza F | B10: =IF(Genel_Tablo!E10="","",IF(IF(Hedefler!$D$4="≥",Genel_Tablo!E10>=Hedefler!$E$4,Genel_Tablo!E10<=Hedefler!$E$4),Hedefler!$F$4,0)) -> 0 | C10: =IF(Genel_Tablo!G10="","",IF(IF(Hedefler!$D$5="≥",Genel_Tablo!G10>=Hedefler!$E$5,Genel_Tablo!G10<=Hedefler!$E$5),Hedefler!$F$5,0)) -> 0 | D10: =IF(Genel_Tablo!H10="","",IF(IF(Hedefler!$D$6="≥",Genel_Tablo!H10>=Hedefler!$E$6,Genel_Tablo!H10<=Hedefler!$E$6),Hedefler!$F$6,0)) -> 8 | E10: =IF(Genel_Tablo!I10="","",IF(IF(Hedefler!$D$7="≥",Genel_Tablo!I10>=Hedefler!$E$7,Genel_Tablo!I10<=Hedefler!$E$7),Hedefler!$F$7,0)) -> 0 | F10: =IF(Genel_Tablo!J10="","",IF(IF(Hedefler!$D$8="≥",Genel_Tablo!J10>=Hedefler!$E$8,Genel_Tablo!J10<=Hedefler!$E$8),Hedefler!$F$8,0)) -> 5 | G10: =IF(Genel_Tablo!L10="","",IF(IF(Hedefler!$D$9="≥",Genel_Tablo!L10>=Hedefler!$E$9,Genel_Tablo!L10<=Hedefler!$E$9),Hedefler!$F$9,0)) -> 0 | H10: =IF(Genel_Tablo!N10="","",IF(IF(Hedefler!$D$10="≥",Genel_Tablo!N10>=Hedefler!$E$10,Genel_Tablo!N10<=Hedefler!$E$10),Hedefler!$F$10,0)) -> 0 | I10: =IF(Genel_Tablo!O10="","",IF(IF(Hedefler!$D$11="≥",Genel_Tablo!O10>=Hedefler!$E$11,Genel_Tablo!O10<=Hedefler!$E$11),Hedefler!$F$11,0)) -> 6 | J10: =IF(Genel_Tablo!P10="","",IF(IF(Hedefler!$D$12="≥",Genel_Tablo!P10>=Hedefler!$E$12,Genel_Tablo!P10<=Hedefler!$E$12),Hedefler!$F$12,0)) -> 6 | K10: =IF(Genel_Tablo!Q10="","",IF(IF(Hedefler!$D$13="≥",Genel_Tablo!Q10>=Hedefler!$E$13,Genel_Tablo!Q10<=Hedefler!$E$13),Hedefler!$F$13,0)) -> 6 | L10: =IF(Genel_Tablo!R10="","",IF(IF(Hedefler!$D$14="≥",Genel_Tablo!R10>=Hedefler!$E$14,Genel_Tablo!R10<=Hedefler!$E$14),Hedefler!$F$14,0)) -> 6 | M10: =IF(Genel_Tablo!S10="","",IF(IF(Hedefler!$D$15="≥",Genel_Tablo!S10>=Hedefler!$E$15,Genel_Tablo!S10<=Hedefler!$E$15),Hedefler!$F$15,0)) -> 4 | N10: =IF(Genel_Tablo!T10="","",IF(IF(Hedefler!$D$16="≥",Genel_Tablo!T10>=Hedefler!$E$16,Genel_Tablo!T10<=Hedefler!$E$16),Hedefler!$F$16,0)) -> 0 | O10: =IF(Genel_Tablo!U10="","",IF(IF(Hedefler!$D$17="≥",Genel_Tablo!U10>=Hedefler!$E$17,Genel_Tablo!U10<=Hedefler!$E$17),Hedefler!$F$17,0)) -> 0 | P10: =IF(Genel_Tablo!V10="","",IF(IF(Hedefler!$D$18="≥",Genel_Tablo!V10>=Hedefler!$E$18,Genel_Tablo!V10<=Hedefler!$E$18),Hedefler!$F$18,0)) -> 0 | Q10: =IF(Genel_Tablo!W10="","",IF(IF(Hedefler!$D$19="≥",Genel_Tablo!W10>=Hedefler!$E$19,Genel_Tablo!W10<=Hedefler!$E$19),Hedefler!$F$19,0)) -> 0 | S10: =SUM(B10:Q10) -> 41
A11: =Genel_Tablo!A11 -> Mağaza G | B11: =IF(Genel_Tablo!E11="","",IF(IF(Hedefler!$D$4="≥",Genel_Tablo!E11>=Hedefler!$E$4,Genel_Tablo!E11<=Hedefler!$E$4),Hedefler!$F$4,0)) -> 15 | C11: =IF(Genel_Tablo!G11="","",IF(IF(Hedefler!$D$5="≥",Genel_Tablo!G11>=Hedefler!$E$5,Genel_Tablo!G11<=Hedefler!$E$5),Hedefler!$F$5,0)) -> 15 | D11: =IF(Genel_Tablo!H11="","",IF(IF(Hedefler!$D$6="≥",Genel_Tablo!H11>=Hedefler!$E$6,Genel_Tablo!H11<=Hedefler!$E$6),Hedefler!$F$6,0)) -> 8 | E11: =IF(Genel_Tablo!I11="","",IF(IF(Hedefler!$D$7="≥",Genel_Tablo!I11>=Hedefler!$E$7,Genel_Tablo!I11<=Hedefler!$E$7),Hedefler!$F$7,0)) -> 5 | F11: =IF(Genel_Tablo!J11="","",IF(IF(Hedefler!$D$8="≥",Genel_Tablo!J11>=Hedefler!$E$8,Genel_Tablo!J11<=Hedefler!$E$8),Hedefler!$F$8,0)) -> 5 | G11: =IF(Genel_Tablo!L11="","",IF(IF(Hedefler!$D$9="≥",Genel_Tablo!L11>=Hedefler!$E$9,Genel_Tablo!L11<=Hedefler!$E$9),Hedefler!$F$9,0)) -> 4 | H11: =IF(Genel_Tablo!N11="","",IF(IF(Hedefler!$D$10="≥",Genel_Tablo!N11>=Hedefler!$E$10,Genel_Tablo!N11<=Hedefler!$E$10),Hedefler!$F$10,0)) -> 0 | I11: =IF(Genel_Tablo!O11="","",IF(IF(Hedefler!$D$11="≥",Genel_Tablo!O11>=Hedefler!$E$11,Genel_Tablo!O11<=Hedefler!$E$11),Hedefler!$F$11,0)) -> 6 | J11: =IF(Genel_Tablo!P11="","",IF(IF(Hedefler!$D$12="≥",Genel_Tablo!P11>=Hedefler!$E$12,Genel_Tablo!P11<=Hedefler!$E$12),Hedefler!$F$12,0)) -> 6 | K11: =IF(Genel_Tablo!Q11="","",IF(IF(Hedefler!$D$13="≥",Genel_Tablo!Q11>=Hedefler!$E$13,Genel_Tablo!Q11<=Hedefler!$E$13),Hedefler!$F$13,0)) -> 0 | L11: =IF(Genel_Tablo!R11="","",IF(IF(Hedefler!$D$14="≥",Genel_Tablo!R11>=Hedefler!$E$14,Genel_Tablo!R11<=Hedefler!$E$14),Hedefler!$F$14,0)) -> 6 | M11: =IF(Genel_Tablo!S11="","",IF(IF(Hedefler!$D$15="≥",Genel_Tablo!S11>=Hedefler!$E$15,Genel_Tablo!S11<=Hedefler!$E$15),Hedefler!$F$15,0)) -> 4 | N11: =IF(Genel_Tablo!T11="","",IF(IF(Hedefler!$D$16="≥",Genel_Tablo!T11>=Hedefler!$E$16,Genel_Tablo!T11<=Hedefler!$E$16),Hedefler!$F$16,0)) -> 0 | O11: =IF(Genel_Tablo!U11="","",IF(IF(Hedefler!$D$17="≥",Genel_Tablo!U11>=Hedefler!$E$17,Genel_Tablo!U11<=Hedefler!$E$17),Hedefler!$F$17,0)) -> 4 | P11: =IF(Genel_Tablo!V11="","",IF(IF(Hedefler!$D$18="≥",Genel_Tablo!V11>=Hedefler!$E$18,Genel_Tablo!V11<=Hedefler!$E$18),Hedefler!$F$18,0)) -> 0 | Q11: =IF(Genel_Tablo!W11="","",IF(IF(Hedefler!$D$19="≥",Genel_Tablo!W11>=Hedefler!$E$19,Genel_Tablo!W11<=Hedefler!$E$19),Hedefler!$F$19,0)) -> 0 | S11: =SUM(B11:Q11) -> 78
A12: =Genel_Tablo!A12 -> Mağaza H | B12: =IF(Genel_Tablo!E12="","",IF(IF(Hedefler!$D$4="≥",Genel_Tablo!E12>=Hedefler!$E$4,Genel_Tablo!E12<=Hedefler!$E$4),Hedefler!$F$4,0)) -> 0 | C12: =IF(Genel_Tablo!G12="","",IF(IF(Hedefler!$D$5="≥",Genel_Tablo!G12>=Hedefler!$E$5,Genel_Tablo!G12<=Hedefler!$E$5),Hedefler!$F$5,0)) -> 15 | D12: =IF(Genel_Tablo!H12="","",IF(IF(Hedefler!$D$6="≥",Genel_Tablo!H12>=Hedefler!$E$6,Genel_Tablo!H12<=Hedefler!$E$6),Hedefler!$F$6,0)) -> 8 | E12: =IF(Genel_Tablo!I12="","",IF(IF(Hedefler!$D$7="≥",Genel_Tablo!I12>=Hedefler!$E$7,Genel_Tablo!I12<=Hedefler!$E$7),Hedefler!$F$7,0)) -> 0 | F12: =IF(Genel_Tablo!J12="","",IF(IF(Hedefler!$D$8="≥",Genel_Tablo!J12>=Hedefler!$E$8,Genel_Tablo!J12<=Hedefler!$E$8),Hedefler!$F$8,0)) -> 5 | G12: =IF(Genel_Tablo!L12="","",IF(IF(Hedefler!$D$9="≥",Genel_Tablo!L12>=Hedefler!$E$9,Genel_Tablo!L12<=Hedefler!$E$9),Hedefler!$F$9,0)) -> 4 | H12: =IF(Genel_Tablo!N12="","",IF(IF(Hedefler!$D$10="≥",Genel_Tablo!N12>=Hedefler!$E$10,Genel_Tablo!N12<=Hedefler!$E$10),Hedefler!$F$10,0)) -> 6 | I12: =IF(Genel_Tablo!O12="","",IF(IF(Hedefler!$D$11="≥",Genel_Tablo!O12>=Hedefler!$E$11,Genel_Tablo!O12<=Hedefler!$E$11),Hedefler!$F$11,0)) -> 6 | J12: =IF(Genel_Tablo!P12="","",IF(IF(Hedefler!$D$12="≥",Genel_Tablo!P12>=Hedefler!$E$12,Genel_Tablo!P12<=Hedefler!$E$12),Hedefler!$F$12,0)) -> 0 | K12: =IF(Genel_Tablo!Q12="","",IF(IF(Hedefler!$D$13="≥",Genel_Tablo!Q12>=Hedefler!$E$13,Genel_Tablo!Q12<=Hedefler!$E$13),Hedefler!$F$13,0)) -> 6 | L12: =IF(Genel_Tablo!R12="","",IF(IF(Hedefler!$D$14="≥",Genel_Tablo!R12>=Hedefler!$E$14,Genel_Tablo!R12<=Hedefler!$E$14),Hedefler!$F$14,0)) -> 6 | M12: =IF(Genel_Tablo!S12="","",IF(IF(Hedefler!$D$15="≥",Genel_Tablo!S12>=Hedefler!$E$15,Genel_Tablo!S12<=Hedefler!$E$15),Hedefler!$F$15,0)) -> 0 | N12: =IF(Genel_Tablo!T12="","",IF(IF(Hedefler!$D$16="≥",Genel_Tablo!T12>=Hedefler!$E$16,Genel_Tablo!T12<=Hedefler!$E$16),Hedefler!$F$16,0)) -> 0 | O12: =IF(Genel_Tablo!U12="","",IF(IF(Hedefler!$D$17="≥",Genel_Tablo!U12>=Hedefler!$E$17,Genel_Tablo!U12<=Hedefler!$E$17),Hedefler!$F$17,0)) -> 0 | P12: =IF(Genel_Tablo!V12="","",IF(IF(Hedefler!$D$18="≥",Genel_Tablo!V12>=Hedefler!$E$18,Genel_Tablo!V12<=Hedefler!$E$18),Hedefler!$F$18,0)) -> 3 | Q12: =IF(Genel_Tablo!W12="","",IF(IF(Hedefler!$D$19="≥",Genel_Tablo!W12>=Hedefler!$E$19,Genel_Tablo!W12<=Hedefler!$E$19),Hedefler!$F$19,0)) -> 3 | S12: =SUM(B12:Q12) -> 62

Sheet Hedefler
A1: Hedefler ve Performans Katsayıları
A3: Kod | B3: Gösterge | C3: Birim | D3: Yön | E3: Hedef | F3: Katsayı
A4: SAT | B4: Satış bütçe sapması | C4: % | D4: ≥ | E4: 0 | F4: 15
A5: L12 | B5: Mağaza katkısı bütçe sapması (Line 12) | C5: % | D5: ≥ | E5: 0 | F5: 15
A6: CRM | B6: CRM satış oranı | C6: % | D6: ≥ | E6: 0.14 | F6: 8
A7: IPT | B7: Paket servis iptal oranı | C7: % | D7: ≤ | E7: 0.07 | F7: 5
A8: ACK | B8: Platform açıklık oranı | C8: % | D8: ≥ | E8: 0.9 | F8: 5
A9: OE | B9: Origin espresso oranı | C9: % | D9: ≥ | E9: 0.18 | F9: 4
A10: FAF | B10: Food attach geçen yıla göre fark | C10: puan | D10: ≥ | E10: 0 | F10: 6
A11: FMO | B11: Food mark-out oranı | C11: % | D11: ≤ | E11: 0.08 | F11: 6
A12: ENV | B12: Envanter sayım farkı | C12: % | D12: ≥ | E12: -0.005 | F12: 6
A13: EGT | B13: Eğitim tamamlama | C13: % | D13: ≥ | E13: 0.95 | F13: 6
A14: TRN | B14: Turnover (yıl başından) | C14: % | D14: ≤ | E14: 0.5 | F14: 6
A15: KSF | B15: Kahve sohbeti hedef farkı | C15: adet | D15: ≥ | E15: 0 | F15: 4
... A19: RSA | B19: RSA denetim puanı | C19: puan | D19: ≥ | E19: 90 | F19: 3
E20: Toplam | F20: =SUM(F4:F19) -> 100
A21: =IF(F20=100,"Katsayı toplamı 100.","UYARI: katsayı toplamı 100 değil.") -> Katsayı toplamı 100.
A23: Hedef değerleri orijinal dosyadaki hedef satırından alınmıştır. Katsayılar örnek değerdir; kurumun performans sistemine göre değiştirilir.

Sheet Satis
A1: Anahtar | B1: Dönem | C1: Mağaza | D1: ADT | E1: Ortalama Adisyon (TL) | F1: Net Satış (TL) | G1: Satış Bütçesi (TL)
A2: =B2&"|"&C2 -> P1|Mağaza A | B2: P1 | C2: Mağaza A | D2: 689 | E2: 127.25 | F2: 2717933 | G2: 2851870
A3: =B3&"|"&C3 -> P1|Mağaza B | B3: P1 | C3: Mağaza B | D3: 501 | E3: 127.2 | F3: 1975543 | G3: 2110569
A4: =B4&"|"&C4 -> P1|Mağaza C | B4: P1 | C4: Mağaza C | D4: 361 | E4: 118.97 | F4: 1331393 | G4: 1426592
A5: =B5&"|"&C5 -> P1|Mağaza D | B5: P1 | C5: Mağaza D | D5: 852 | E5: 132.03 | F5: 3487176 | G5: 3302289
A6: =B6&"|"&C6 -> P1|Mağaza E | B6: P1 | C6: Mağaza E | D6: 569 | E6: 112.4 | F6: 1982624 | G6: 2005551
A7: =B7&"|"&C7 -> P1|Mağaza F | B7: P1 | C7: Mağaza F | D7: 526 | E7: 105.39 | F7: 1718489 | G7: 1654062
A8: =B8&"|"&C8 -> P1|Mağaza G | B8: P1 | C8: Mağaza G | D8: 401 | E8: 132.49 | F8: 1646983 | G8: 1720865
A9: =B9&"|"&C9 -> P1|Mağaza H | B9: P1 | C9: Mağaza H | D9: 467 | E9: 128.91 | F9: 1866230 | G9: 1774440
A10: =B10&"|"&C10 -> P2|Mağaza A | B10: P2 | C10: Mağaza A | D10: 689 | E10: 108.8 | F10: 2098970 | G10: 1952601
A11: =B11&"|"&C11 -> P2|Mağaza B | B11: P2 | C11: Mağaza B | D11: 496 | E11: 111.28 | F11: 1545457 | G11: 1487228
A12: =B12&"|"&C12 -> P2|Mağaza C | B12: P2 | C12: Mağaza C | D12: 420 | E12: 131.17 | F12: 1542559 | G12: 1501520
A13: =B13&"|"&C13 -> P2|Mağaza D | B13: P2 | C13: Mağaza D | D13: 893 | E13: 121.18 | F13: 3029985 | G13: 3125958
... A25: =B25&"|"&C25 -> P3|Mağaza H | B25: P3 | C25: Mağaza H | D25: 530 | E25: 110.9 | F25: 1822087 | G25: 1901094

Sheet PnL
A1: Anahtar | B1: Dönem | C1: Mağaza | D1: Net Satış | E1: COGS | F1: Royalty | G1: Personel | H1: Kontrol Edilebilir | I1: Kira | J1: Amortisman | K1: Mağaza Katkısı (Line 12) | L1: Mağaza Katkısı Bütçe | M1: Sapma Açıklaması
A2: =B2&"|"&C2 -> P1|Mağaza A | B2: P1 | C2: Mağaza A | D2: 2838390 | E2: 758140 | F2: 198687 | G2: 361097 | H2: 230726 | I2: 344814 | J2: 122812 | K2: 822114 | L2: 725446
A3: =B3&"|"&C3 -> P1|Mağaza B | B3: P1 | C3: Mağaza B | D3: 1994640 | E3: 475452 | F3: 139625 | G3: 248917 | H3: 171496 | I3: 296604 | J3: 52368 | K3: 610178 | L3: 612536 | M3: Satış bütçenin altında kaldı; mağaza katkısı bundan etkilendi, diğer kalemler stabil.
A4: =B4&"|"&C4 -> P1|Mağaza C | B4: P1 | C4: Mağaza C | D4: 1483284 | E4: 351535 | F4: 103830 | G4: 231704 | H4: 137513 | I4: 161303 | J4: 43763 | K4: 453636 | L4: 409744 | M4: Satış bütçenin üzerinde; personel maliyeti vardiya planıyla dengelendi.
A5: =B5&"|"&C5 -> P1|Mağaza D | B5: P1 | C5: Mağaza D | D5: 3269916 | E5: 837284 | F5: 228894 | G5: 410261 | H5: 291113 | I5: 435578 | J5: 73340 | K5: 993446 | L5: 1023443 | M5: Kontrol edilebilir giderlerde bakım faturası yansıdı.
A6: =B6&"|"&C6 -> P1|Mağaza E | B6: P1 | C6: Mağaza E | D6: 1868937 | E6: 480369 | F6: 130826 | G6: 237713 | H6: 140194 | I6: 241201 | J6: 45544 | K6: 593090 | L6: 678326
A7: =B7&"|"&C7 -> P1|Mağaza F | B7: P1 | C7: Mağaza F | D7: 1728137 | E7: 422837 | F7: 120970 | G7: 262541 | H7: 117227 | I7: 231397 | J7: 83804 | K7: 489361 | L7: 508505 | M7: Kontrol edilebilir giderlerde bakım faturası yansıdı.
A8: =B8&"|"&C8 -> P1|Mağaza G | B8: P1 | C8: Mağaza G | D8: 1345021 | E8: 325129 | F8: 94151 | G8: 157989 | H8: 148872 | I8: 144844 | J8: 45186 | K8: 428850 | L8: 493087 | M8: Kira farkı sözleşme yenilemesinden; emlak ekibine iletildi.
A9: =B9&"|"&C9 -> P1|Mağaza H | B9: P1 | C9: Mağaza H | D9: 1943975 | E9: 471758 | F9: 136078 | G9: 261286 | H9: 201727 | I9: 230833 | J9: 55852 | K9: 586441 | L9: 569514 | M9: Kira farkı sözleşme yenilemesinden; emlak ekibine iletildi.
A10: =B10&"|"&C10 -> P2|Mağaza A | B10: P2 | C10: Mağaza A | D10: 2090805 | E10: 545915 | F10: 146356 | G10: 285578 | H10: 147953 | I10: 305736 | J10: 96248 | K10: 563019 | L10: 508989 | M10: Kontrol edilebilir giderlerde bakım faturası yansıdı.
A11: =B11&"|"&C11 -> P2|Mağaza B | B11: P2 | C11: Mağaza B | D11: 1571695 | E11: 407228 | F11: 110019 | G11: 241050 | H11: 128375 | I11: 215576 | J11: 67971 | K11: 401476 | L11: 424914
A12: =B12&"|"&C12 -> P2|Mağaza C | B12: P2 | C12: Mağaza C | D12: 1246908 | E12: 293379 | F12: 87284 | G12: 172031 | H12: 124814 | I12: 174709 | J12: 34846 | K12: 359845 | L12: 411766
A13: =B13&"|"&C13 -> P2|Mağaza D | B13: P2 | C13: Mağaza D | D13: 2845844 | E13: 760630 | F13: 199209 | G13: 405489 | H13: 269899 | I13: 258103 | J13: 103616 | K13: 848898 | L13: 785407
A14: =B14&"|"&C14 -> P2|Mağaza E | B14: P2 | C14: Mağaza E | D14: 1727593 | E14: 405019 | F14: 120932 | G14: 233255 | H14: 173482 | I14: 192444 | J14: 48746 | K14: 553715 | L14: 528064 | M14: Kontrol edilebilir giderlerde bakım faturası yansıdı.
A15: =B15&"|"&C15 -> P2|Mağaza F | B15: P2 | C15: Mağaza F | D15: 1807827 | E15: 473911 | F15: 126548 | G15: 277493 | H15: 183133 | I15: 268584 | J15: 88033 | K15: 390125 | L15: 392248
A16: =B16&"|"&C16 -> P2|Mağaza G | B16: P2 | C16: Mağaza G | D16: 1531692 | E16: 352186 | F16: 107218 | G16: 196212 | H16: 170372 | I16: 163847 | J16: 34256 | K16: 507601 | L16: 533619 | M16: Kontrol edilebilir giderlerde bakım faturası yansıdı.
A17: =B17&"|"&C17 -> P2|Mağaza H | B17: P2 | C17: Mağaza H | D17: 1418794 | E17: 367494 | F17: 99316 | G17: 197272 | H17: 141785 | I17: 163512 | J17: 54925 | K17: 394490 | L17: 427000
A18: =B18&"|"&C18 -> P3|Mağaza A | B18: P3 | C18: Mağaza A | D18: 2181203 | E18: 588490 | F18: 152684 | G18: 261264 | H18: 207622 | I18: 277982 | J18: 55451 | K18: 637710 | L18: 687260 | M18: Kira farkı sözleşme yenilemesinden; emlak ekibine iletildi.
A19: =B19&"|"&C19 -> P3|Mağaza B | B19: P3 | C19: Mağaza B | D19: 1744134 | E19: 387360 | F19: 122089 | G19: 232980 | H19: 128324 | I19: 162638 | J19: 41869 | K19: 668874 | L19: 632223 | M19: Kira farkı sözleşme yenilemesinden; emlak ekibine iletildi.
A20: =B20&"|"&C20 -> P3|Mağaza C | B20: P3 | C20: Mağaza C | D20: 1403769 | E20: 347315 | F20: 98264 | G20: 183577 | H20: 113798 | I20: 182141 | J20: 31107 | K20: 447567 | L20: 407872
A21: =B21&"|"&C21 -> P3|Mağaza D | B21: P3 | C21: Mağaza D | D21: 3165404 | E21: 696493 | F21: 221578 | G21: 412353 | H21: 242823 | I21: 362763 | J21: 74236 | K21: 1155158 | L21: 1269993 | M21: Satış bütçenin altında kaldı; mağaza katkısı bundan etkilendi, diğer kalemler stabil.
A22: =B22&"|"&C22 -> P3|Mağaza E | B22: P3 | C22: Mağaza E | D22: 2470360 | E22: 611406 | F22: 172925 | G22: 308966 | H22: 191989 | I22: 298318 | J22: 119894 | K22: 766862 | L22: 719284 | M22: Satış bütçenin altında kaldı; mağaza katkısı bundan etkilendi, diğer kalemler stabil.
A23: =B23&"|"&C23 -> P3|Mağaza F | B23: P3 | C23: Mağaza F | D23: 2184827 | E23: 526445 | F23: 152938 | G23: 329143 | H23: 215288 | I23: 245065 | J23: 53011 | K23: 662937 | L23: 682017
A24: =B24&"|"&C24 -> P3|Mağaza G | B24: P3 | C24: Mağaza G | D24: 1416579 | E24: 325753 | F24: 99161 | G24: 165243 | H24: 92715 | I24: 197293 | J24: 56450 | K24: 479964 | L24: 462952 | M24: Satış bütçenin altında kaldı; mağaza katkısı bundan etkilendi, diğer kalemler stabil.
A25: =B25&"|"&C25 -> P3|Mağaza H | B25: P3 | C25: Mağaza H | D25: 2004039 | E25: 502530 | F25: 140283 | G25: 234543 | H25: 195930 | I25: 287533 | J25: 62677 | K25: 580543 | L25: 568645 | M25: Kira farkı sözleşme yenilemesinden; emlak ekibine iletildi.

Sheet CRM
A1: Anahtar | B1: Dönem | C1: Mağaza | D1: İşlem | E1: CRM İşlem | F1: Net Satış | G1: CRM Satış
A2: =B2&"|"&C2 -> P1|Mağaza A | B2: P1 | C2: Mağaza A | D2: 21359 | E2: 3352 | F2: 2563080 | G2: 383111
A3: =B3&"|"&C3 -> P1|Mağaza B | B3: P1 | C3: Mağaza B | D3: 15531 | E3: 2419 | F3: 1863720 | G3: 276513
A4: =B4&"|"&C4 -> P1|Mağaza C | B4: P1 | C4: Mağaza C | D4: 11191 | E4: 1958 | F4: 1342920 | G4: 223816
A5: =B5&"|"&C5 -> P1|Mağaza D | B5: P1 | C5: Mağaza D | D5: 26412 | E5: 3902 | F5: 3169440 | G5: 445976
A6: =B6&"|"&C6 -> P1|Mağaza E | B6: P1 | C6: Mağaza E | D6: 17639 | E6: 3304 | F6: 2116680 | G6: 377610
A7: =B7&"|"&C7 -> P1|Mağaza F | B7: P1 | C7: Mağaza F | D7: 16306 | E7: 2101 | F7: 1956720 | G7: 240133
A8: =B8&"|"&C8 -> P1|Mağaza G | B8: P1 | C8: Mağaza G | D8: 12431 | E8: 2056 | F8: 1491720 | G8: 234970
A9: =B9&"|"&C9 -> P1|Mağaza H | B9: P1 | C9: Mağaza H | D9: 14477 | E9: 2573 | F9: 1737240 | G9: 294084
A10: =B10&"|"&C10 -> P2|Mağaza A | B10: P2 | C10: Mağaza A | D10: 19292 | E10: 2716 | F10: 2315040 | G10: 310364
A11: =B11&"|"&C11 -> P2|Mağaza B | B11: P2 | C11: Mağaza B | D11: 13888 | E11: 1897 | F11: 1666560 | G11: 216795
A12: =B12&"|"&C12 -> P2|Mağaza C | B12: P2 | C12: Mağaza C | D12: 11760 | E12: 1378 | F12: 1411200 | G12: 157453
A13: =B13&"|"&C13 -> P2|Mağaza D | B13: P2 | C13: Mağaza D | D13: 25004 | E13: 4873 | F13: 3000480 | G13: 556931
... A25: =B25&"|"&C25 -> P3|Mağaza H | B25: P3 | C25: Mağaza H | D25: 16430 | E25: 2671 | F25: 1971600 | G25: 305253

Sheet Paket_Servis
A1: Anahtar | B1: Dönem | C1: Mağaza | D1: Platform 1 İşlem | E1: Platform 1 İptal | F1: Platform 2 İşlem | G1: Platform 2 İptal | H1: Platform 1 Açıklık | I1: Platform 2 Açıklık | J1: Paket Satış Payı
A2: =B2&"|"&C2 -> P1|Mağaza A | B2: P1 | C2: Mağaza A | D2: 549 | E2: 45 | F2: 635 | G2: 25 | H2: 0.88 | I2: 0.863 | J2: 0.198
